Workbook

Sheet DATA
B2: 45658 | E2: 45689 | H2: 45717 | J2: 45748 | L2: 45778 | O2: 45809 | Q2: 45839 | S2: 45870 | U2: 45901 | W2: 45931 | Y2: 45962 | AA2: 45992 | AC2: 46023 | AE2: 46054 | AG2: 46082 | AI2: 46113 | AK2: 46143 | AM2: 46174
B3: Item | C3: Qty | E3: Item | F3: Qty | H3: Item | I3: Qty | J3: Item | K3: Qty | L3: Item | M3: Qty | O3: Item | P3: Qty | Q3: Item | R3: Qty | S3: Item | T3: Qty | U3: Item | V3: Qty | W3: Item | X3: Qty | Y3: Item | Z3: Qty | AA3: Item | AB3: Qty | AC3: Item | AD3: Qty | AE3: Item | AF3: Qty | AG3: Item | AH3: Qty | AI3: Item | AJ3: Qty | AK3: Item | AL3: Qty | AM3: Item | AN3: Qty
B4: 003-0100-001-T | C4: -28 | E4: 003-0100-001-T | F4: -70 | H4: 003-0100-001-T | I4: -68 | J4: 003-0100-001-T | K4: -30 | L4: 003-0100-001-T | M4: -24 | O4: 001-0136-002-T | P4: -1 | Q4: 003-0100-001-T | R4: -62 | S4: 001-0136-002-T | T4: -1 | U4: 003-0100-001-T | V4: -63 | W4: 003-0100-001-T | X4: -71 | Y4: 003-0100-001-T | Z4: -12 | AA4: 003-0100-001-T | AB4: -4 | AC4: 003-0100-001-T | AD4: -8 | AE4: 003-0100-001-T | AF4: -16 | AG4: 003-0100-001-T | AH4: -40 | AI4: 003-0100-001-T | AJ4: -34 | AK4: 003-0100-001-T | AL4: -40 | AM4: 003-0100-001-T | AN4: -54
B5: 003-0100-T | C5: -38 | E5: 003-0100-T | F5: -64 | H5: 003-0100-T | I5: -23 | J5: 003-0100-T | K5: -30 | L5: 003-0100-T | M5: -36 | O5: 003-0100-001-T | P5: -30 | Q5: 003-0100-T | R5: -44 | S5: 003-0100-001-T | T5: -78 | U5: 003-0100-T | V5: -54 | W5: 003-0100-T | X5: -58 | Y5: 003-0100-T | Z5: -8 | AA5: 003-0100-T | AB5: -10 | AC5: 003-0100-T | AD5: -8 | AE5: 003-0100-T | AF5: -48 | AG5: 003-0100-T | AH5: -53 | AI5: 003-0100-T | AJ5: -33 | AK5: 003-0100-T | AL5: -22 | AM5: 003-0100-T | AN5: -38
B6: 003-0121-001-T | C6: -20 | E6: 003-0121-005-T | F6: -1906 | H6: 003-0121-005-T | I6: -343 | J6: 003-0121-001-T | K6: -215.99 | L6: 003-0121-001-T | M6: -280 | O6: 003-0100-T | P6: -62 | Q6: 003-0121-001-T | R6: -88 | S6: 003-0100-T | T6: -36 | U6: 003-0121-001-T | V6: -120 | W6: 003-0121-001-T | X6: -80 | Y6: 003-0121-005-T | Z6: -48 | AA6: 003-0121-001-T | AB6: -66 | AC6: 003-0121-005-T | AD6: -896 | AE6: 003-0121-005-T | AF6: -1497 | AG6: 003-0121-005-T | AH6: -913 | AI6: 003-0121-001-T | AJ6: -8 | AK6: 003-0121-001-T | AL6: -8 | AM6: 003-0121-005-T | AN6: -696
B7: 003-0121-005-T | C7: -1680 | E7: 003-3447 | F7: -364 | H7: 003-3447 | I7: -230 | J7: 003-0121-005-T | K7: -224 | L7: 003-0121-005-t | M7: -1232 | O7: 003-0121-001-T | P7: -104 | Q7: 003-0121-005-T | R7: -1040 | S7: 003-0121-001-T | T7: -40 | U7: 003-0121-005-T | V7: -648 | W7: 003-0121-005-T | X7: -802 | Y7: 003-2707-001 | Z7: -8 | AA7: 003-0121-005-T | AB7: -176 | AC7: 003-3430 | AD7: -28 | AE7: 003-3447 | AF7: -50 | AG7: 003-3430 | AH7: -98 | AI7: 003-0121-005-T | AJ7: -866 | AK7: 003-0121-005-T | AL7: -288 | AM7: 003-0121-T | AN7: -1
B8: 003-3447 | C8: -176 | E8: 014-0120-001-T | F8: -50 | H8: 014-0120-001-T | I8: -87.5 | J8: 003-3447 | K8: -30 | L8: 003-3447 | M8: -64 | O8: 003-0121-005-T | P8: -134 | Q8: 003-3447 | R8: -21 | S8: 003-0121-005-T | T8: -533 | U8: 003-3447 | V8: -83 | W8: 003-2992-001 | X8: -9 | Y8: 003-3430 | Z8: -14 | AA8: 003-3430 | AB8: -14 | AC8: 003-3447 | AD8: -81 | AE8: 010-0187-004-T | AF8: -2 | AG8: 003-3447 | AH8: -185 | AI8: 003-3430 | AJ8: -116 | AK8: 003-3430 | AL8: -88 | AM8: 003-3430 | AN8: -98
B9: 005-0108-001-T | C9: -2 | E9: 014-0205-004-T | F9: -287 | H9: 014-0205-003-T | I9: -27 | J9: 005-0108-T | K9: -6 | L9: 005-0108-T | M9: -8 | O9: 003-0128-001-t | P9: -24 | Q9: 014-0120-001-T | R9: -73 | S9: 003-3447 | T9: -79 | U9: 010-4835 | V9: -2 | W9: 003-3430 | X9: -28 | Y9: 003-3447 | Z9: -7 | AA9: 003-3447 | AB9: -12 | AC9: 014-0205-003-T | AD9: -12 | AE9: 010-0187-004-T-LB | AF9: -2 | AG9: 010-0575-002-T | AH9: -5 | AI9: 003-3447 | AJ9: -65 | AK9: 003-3447 | AL9: -54 | AM9: 003-3447 | AN9: -51
B10: 014-0120-001-T | C10: -23.1 | E10: 014-0537-001-T | F10: -87 | H10: 014-0205-004-T | I10: -176 | J10: 014-0120-001-T | K10: -15 | L10: 014-0120-001-T | M10: -28.5 | O10: 003-0128-002-t | P10: -48 | Q10: 014-0205-004-T | R10: -31 | S10: 014-0120-001-T | T10: -46.1 | U10: 014-0120-001-t | V10: -73.35 | W10: 003-3447 | X10: -48 | Y10: 014-0120-001-T | Z10: -18.8 | AA10: 014-0205-003-T | AB10: -8 | AC10: 014-0205-004-T | AD10: -16 | AE10: 014-0120-001-T | AF10: -41.3 | AG10: 014-0120-001-T | AH10: -39 | AI10: 005-0108-T | AJ10: -2 | AK10: 010-0187-004-T-LB | AL10: -2 | AM10: 005-0104-T | AN10: -2
B11: 014-0120-003-t | C11: -4.4 | E11: 015-2945 | F11: -7 | H11: 014-1876 | I11: -17 | J11: 014-0205-004-T | K11: -41 | L11: 014-0205-003-T | M11: -16 | O11: 003-3447 | P11: -32 | Q11: 015-2945 | R11: -24 | S11: 014-0205-003-T | T11: -6 | U11: 014-0205-003-T | V11: -18 | W11: 014-0120-001-T | X11: -78.95 | Y11: 014-0205-003-T | Z11: -24 | AA11: 014-0205-004-T | AB11: -26 | AC11: 014-1876 | AD11: -10 | AE11: 014-0205-003-T | AF11: -9 | AG11: 014-0205-003-T | AH11: -4 | AI11: 014-0120-001-T | AJ11: -21.4 | AK11: 014-0120-001-t | AL11: -2 | AM11: 005-0108-001-T | AN11: -3
B12: 014-0205-003-T | C12: -4 | E12: 019-1172 | F12: -16 | H12: 015-2945 | I12: -5 | J12: 014-0205-005-T | K12: -4 | L12: 014-0205-004-T | M12: -80 | O12: 005-0108-T | P12: -7 | Q12: 019-1172 | R12: -14 | S12: 014-0205-004-T | T12: -46 | U12: 014-0205-004-T | V12: -62 | W12: 014-0205-003-T | X12: -3 | Y12: 014-0205-004-T | Z12: -13 | AA12: 014-1876 | AB12: -8 | AC12: 019-1172 | AD12: -2 | AE12: 014-0205-004-T | AF12: -167 | AG12: 014-0205-004-T | AH12: -111 | AI12: 014-0205-003-T | AJ12: -4 | AK12: 014-0205-003-T | AL12: -16 | AM12: 010-0187-004-T | AN12: -2
B13: 014-0205-004-T | C13: -174 | E13: 019-1242 | F13: -48 | H13: 019-1172 | I13: -12 | J13: 014-1876 | K13: -24 | L13: 014-1876 | M13: -8 | O13: 014-0120-001-T | P13: -91 | Q13: 019-1242 | R13: -80 | S13: 014-1876 | T13: -10 | U13: 014-1876 | V13: -12 | W13: 014-0205-004-T | X13: -68 | Y13: 015-2945 | Z13: -28 | AA13: 019-1172 | AB13: -2 | AC13: 019-1242 | AD13: -12 | AE13: 015-2945 | AF13: -44.5 | AG13: 014-1876 | AH13: -2 | AI13: 014-0205-004-T | AJ13: -88 | AK13: 014-0205-004-T | AL13: -86 | AM13: 010-0524-T | AN13: -2
B14: 014-0205-005-T | C14: -4 | E14: 026-0125-001-T | F14: -95 | H14: 019-1242 | I14: -72 | J14: 019-1172 | K14: -2 | L14: 015-2945 | M14: -52 | O14: 014-0205-003-T | P14: -6 | Q14: 022-0103-001-T | R14: -8 | S14: 015-2945 | T14: -116 | U14: 019-1172 | V14: -8 | W14: 014-1876 | X14: -8 | Y14: 019-1172 | Z14: -2 | AA14: 020-1603 | AB14: -1 | AC14: 020-1603-002 | AD14: -2 | AE14: 019-1172 | AF14: -8 | AG14: 015-2945 | AH14: -38.5 | AI14: 014-1876 | AJ14: -28 | AK14: 014-0537-001-T | AL14: -8 | AM14: 014-0120-001-T | AN14: -20.2
B15: 014-0537-001-T | C15: -90 | E15: 026-0125-001-T-LB | F15: -80 | H15: 020-1603 | I15: -8 | J15: 020-1603 | K15: -3 | L15: 019-1172 | M15: -9 | O15: 014-0205-004-T | P15: -56 | Q15: 022-0129-004-T | R15: -1 | S15: 019-1172 | T15: -5 | U15: 019-1242 | V15: -72 | W15: 015-2945 | X15: -27.5 | Y15: 019-1242 | Z15: -16 | AA15: 020-1603-002 | AB15: -3 | AC15: 025-1006-T | AD15: -2 | AE15: 019-1242 | AF15: -36 | AG15: 019-1172 | AH15: -12 | AI15: 015-2945 | AJ15: -62.5 | AK15: 015-2945 | AL15: -30 | AM15: 014-0205-004-T | AN15: -58
... B473: 9758-0015-T | C473: -8 | E473: RSA-0518 | F473: -2.2171 | H473: RSK-0101 | I473: -9.9 | J473: FAC0565 | K473: -21 | L473: 9292-0053-001-T | M473: -167 | O473: 9292-0048-016-T | P473: -12 | Q473: 9671-0021-T | R473: -52 | S473: 9880-0020-T | T473: -4 | U473: 9674-0010-003-t | V473: -20 | W473: 9754-0007-003-T | X473: -1 | Y473: RAA-0103 | Z473: -1.185 | AA473: WLC6022 | AB473: -5 | AC473: 9941-0177-T | AD473: -3 | AE473: 9739-0001-T | AF473: -68 | AG473: 9599-0023-001-T | AH473: -10 | AI473: 9333-0008-t | AJ473: -38 | AK473: 9574-0015-T | AL473: -6 | AM473: 9292-0048-016-T | AN473: -4
B474: 9869-0003-T | C474: -45 | E474: RSE-0116 | F474: -25 | H474: RSK-0102 | I474: -6 | J474: FAC0572 | K474: -2 | L474: 9293-0034-001-T | M474: -8 | O474: 9292-0048-017-T | P474: -56 | Q474: 9674-0010-003-T | R474: -16 | S474: 9880-0022-006-T | T474: -190 | U474: 9678-0005-T | V474: -88 | W474: 9754-0013-T | X474: -9 | Y474: RAA-0147 | Z474: -2.1 | AA474: (blank) | AC474: 9941-0195-001-T | AD474: -1 | AE474: 9740-0029-T | AF474: -3 | AG474: 9601-0024-001-t | AH474: -2 | AI474: 9333-0025 | AJ474: -1 | AK474: 9577-0046-002-T | AL474: -14 | AM474: 9292-0048-017-T | AN474: -8
B475: 9873-0007-T | C475: -11 | E475: RSF-0104 | F475: -4.2 | H475: RSK-0109 | I475: -0.45 | J475: FAC0625 | K475: -89 | L475: 9293-0036-T | M475: -3 | O475: 9292-0048-018-T | P475: -41 | Q475: 9678-0005-T | R475: -70 | S475: 9880-0022-007-T | T475: -345 | U475: 9681-0001-T | V475: -129 | W475: 9757-0094-T | X475: -3 | Y475: RAA-0158 | Z475: -12.035 | AA475: Grand Total | AB475: -8913.513 | AC475: 9941-0195-002-T | AD475: -3 | AE475: 9740-0034-T | AF475: -4 | AG475: 9667-0002-004-T | AH475: -17 | AI475: 9379-0013-001-t | AJ475: -15 | AK475: 9591-0038-T | AL475: -3 | AM475: 9292-0048-018-T | AN475: -3
B476: 9874-0031-T | C476: -171 | E476: RSH-0115 | F476: -392.5 | H476: SUNDRY-INV | I476: -9 | J476: FAC0631 | K476: -20 | L476: 9293-0037-T | M476: -3 | O476: 9292-0048-022-T | P476: -3 | Q476: 9726-0027-002-T | R476: -12 | S476: 9880-0022-008-T | T476: -380 | U476: 9726-0056-T | V476: -2 | W476: 9757-0096-T | X476: -1 | Y476: RAA-0180 | Z476: -17.45 | AC476: 9941-0223 | AD476: -10 | AE476: 9740-0044-T | AF476: -7 | AG476: 9667-0002-005-T | AH476: -3 | AI476: 9379-0013-t | AJ476: -12 | AK476: 9591-0040-T | AL476: -2 | AM476: 9292-0048-021-T | AN476: -3
B477: 9880-0019-t | C477: -2 | E477: RSH-0139 | F477: -29.9 | H477: SUNDRY-SERVICE | I477: -4 | J477: FAC0643 | K477: -5 | L477: 9293-0053-T | M477: -18 | O477: 9292-0048-024-T | P477: -20 | Q477: 9726-0067-T | R477: -5 | S477: 9880-0022-018-T | T477: -40 | U477: 9726-0115-t | V477: -30 | W477: 9758-0007-T | X477: -4 | Y477: RAA-0226 | Z477: -0.304 | AC477: 9941-0231-001-T | AD477: -1 | AE477: 9745-0011-T | AF477: -32 | AG477: 9669-0007-001-T | AH477: -40 | AI477: 9383-0005-T | AJ477: -1 | AK477: 9591-0051-T | AL477: -1 | AM477: 9292-0048-022-T | AN477: -6
B478: 9880-0020-t | C478: -12 | E478: RSJ-0101 | F478: -40 | H478: (blank) | J478: FAC0666 | K478: -6 | L478: 9293-0068-001-T | M478: -1 | O478: 9292-0048-026-T | P478: -16 | Q478: 9728-0004-002-T | R478: -28 | S478: 9880-0022-026-T | T478: -190 | U478: 9728-0038-001-T | V478: -8 | W478: 9869-0003-T | X478: -16 | Y478: RAA-0227 | Z478: -0.478 | AC478: 9941-0231-003-T | AD478: -6 | AE478: 9745-0018-002-T | AF478: -5 | AG478: 9669-0007-002-T | AH478: -11 | AI478: 9384-0003-001-T | AJ478: -6.5 | AK478: 9591-0068-T | AL478: -2 | AM478: 9292-0048-024-T | AN478: -6
B479: 9880-0037-T | C479: -96 | E479: RSJ-0102 | F479: -34.5756 | H479: Grand Total | I479: -47728.113 | J479: FAC0687 | K479: -1 | L479: 9325-0001 | M479: -7200 | O479: 9292-0048-027-T | P479: -143 | Q479: 9728-0045-t | R479: -20 | S479: 9880-0022-033-T | T479: -320 | U479: 9730-0002-003-T | V479: -1 | W479: 9873-0007-T | X479: -4 | Y479: RAA-0292 | Z479: -1.4 | AC479: 9941-0235-T | AD479: -1 | AE479: 9752-0012-T | AF479: -12 | AG479: 9669-0008-001-T | AH479: -2 | AI479: 9392-0007-T | AJ479: -11.14 | AK479: 9591-0094-T | AL479: -4 | AM479: 9292-0048-025-T | AN479: -10
B480: 9880-0045-T | C480: -1.75 | E480: RSJ-0109 | F480: -3.78 | J480: FAC0692 | K480: -2 | L480: 9326-0019-003-T | M480: -3 | O480: 9292-0052-002-T | P480: -93 | Q480: 9728-0055-T | R480: -10 | S480: 9880-0037-T | T480: -53 | U480: 9737-0010-T | V480: -5 | W480: 9880-0037-T | X480: -12 | Y480: RAA-0310 | Z480: -0.05 | AC480: 9941-0239-T | AD480: -4 | AE480: 9757-0012-T | AF480: -4 | AG480: 9669-0009-001-T | AH480: -1 | AI480: 9392-0028-001-T | AJ480: -36 | AK480: 9591-0097-T | AL480: -8 | AM480: 9292-0048-027-T | AN480: -6
B481: 9880-0047-T | C481: -7 | E481: RSK-0101 | F481: -2.87 | J481: FAC0705 | K481: -23 | L481: 9326-0043-002-T | M481: -152 | O481: 9292-0053-001-T | P481: -166 | Q481: 9738-0001-T | R481: -16 | S481: 9880-0040-T | T481: -20 | U481: 9738-0001-001-T | V481: -36 | W481: 9880-0044-064-T | X481: -1 | Y481: RAA-0320 | Z481: -0.1 | AC481: 9941-0256-T | AD481: -1 | AE481: 9757-0025-T | AF481: -1 | AG481: 9670-0003-001-T | AH481: -10 | AI481: 9392-0037-T | AJ481: -15 | AK481: 9591-0098-T | AL481: -2 | AM481: 9292-0048-034-T | AN481: -6
B482: 9935-0001-051-T | C482: -1 | E482: RSK-0102 | F482: -39 | J482: FAC0712 | K482: -8 | L482: 9326-0046-002-T | M482: -18 | O482: 9292-0055-T | P482: -10 | Q482: 9739-0001-T | R482: -68 | S482: 9880-0044-030-T | T482: -12 | U482: 9738-0001-T | V482: -26 | W482: 9880-0045-T | X482: -9.05 | Y482: RAA-0321 | Z482: -2.5 | AC482: 9941-0277-T | AD482: -6 | AE482: 9757-0036-100-T | AF482: -1 | AG482: 9670-0009-T | AH482: -2 | AI482: 9392-0046-T | AJ482: -45 | AK482: 9591-0108-T | AL482: -2 | AM482: 9292-0048-036-T | AN482: -1
B483: 9935-0010-050-T | C483: -1 | E483: RSK-0109 | F483: -2.81 | J483: FAC-0736 | K483: -245 | L483: 9326-0047-002-T | M483: -20 | O483: 9292-0056-T | P483: -10 | Q483: 9740-0002-T | R483: -7 | S483: 9880-0045-T | T483: -7.008 | U483: 9739-0001-T | V483: -60 | W483: 9881-0003-T | X483: -2 | Y483: RAA-0329 | Z483: -4 | AC483: 9941-0278-T | AD483: -4 | AE483: 9757-0094-T | AF483: -6 | AG483: 9671-0016-001-T | AH483: -28 | AI483: 9392-0074-T | AJ483: -40 | AK483: 9591-0109-T | AL483: -3.5 | AM483: 9292-0048-041-T | AN483: -5
B484: 9935-0010-076-T | C484: -2 | E484: SUNDRY-INV | F484: -10 | J484: FAC0741 | K484: -41.2222 | L484: 9326-0048-002-T | M484: -39 | O484: 9292-0057-T | P484: -5 | Q484: 9740-0034-T | R484: -2 | S484: 9880-0049-001-T | T484: -50 | U484: 9740-0029-T | V484: -1 | W484: 9881-0005-T | X484: -1 | Y484: RAA-0330 | Z484: -6.75 | AC484: 9942-0021-T | AD484: -7 | AE484: 9757-0096-T | AF484: -2 | AG484: 9671-0017-T | AH484: -253 | AI484: 9392-0075-T | AJ484: -54 | AK484: 9591-0110-T | AL484: -5 | AM484: 9292-0052-002-T | AN484: -108
B485: 9941-0065-003-T | C485: -12 | E485: SUNDRY-SERVICE | F485: -18 | J485: FAC0742 | K485: -10 | L485: 9326-0059-002-T | M485: -2 | O485: 9293-0036-T | P485: -2 | Q485: 9740-0043-T | R485: -6 | S485: 9941-0039-005-T | T485: -9 | U485: 9740-0030-T | V485: -1 | W485: 9881-0006-T | X485: -1 | Y485: RAA-0332 | Z485: -2 | AC485: 9965-0009-T | AD485: -1500 | AE485: 9757-0097-001-T | AF485: -12 | AG485: 9671-0018-T | AH485: -26 | AI485: 9392-0099-T | AJ485: -2 | AK485: 9591-0112-T | AL485: -10 | AM485: 9292-0053-001-T | AN485: -148
B486: 9941-0071-T | C486: -29 | E486: (blank) | J486: FAC0743 | K486: -11 | L486: 9326-0060-T | M486: -18 | O486: 9293-0037-T | P486: -2 | Q486: 9740-0044-T | R486: -1 | S486: 9941-0065-003-T | T486: -9 | U486: 9740-0034-T | V486: -3 | W486: 9941-0039-005-T | X486: -6 | Y486: RAA-0341 | Z486: -2 | AC486: 9966-0035-001-T | AD486: -13 | AE486: 9757-0149-t | AF486: -2 | AG486: 9671-0019-T | AH486: -120 | AI486: 9442-0010-T | AJ486: -14 | AK486: 9591-0113-T | AL486: -10 | AM486: 9293-0036-LB | AN486: -40
B487: 9941-0084-T | C487: -8 | E487: Grand Total | F487: -64403.992 | J487: FAC0749 | K487: -21 | L487: 9326-0071-002-T | M487: -20 | O487: 9293-0053-T | P487: -18 | Q487: 9745-0003-T | R487: -11 | S487: 9941-0071-T | T487: -28 | U487: 9740-0043-T | V487: -1 | W487: 9941-0065-003-T | X487: -6 | Y487: RAA-0381 | Z487: -1 | AC487: 9968-0019-T | AD487: -95 | AE487: 9758-0007-T | AF487: -4 | AG487: 9671-0021-001-T | AH487: -2 | AI487: 9442-0014-T | AJ487: -20 | AK487: 9591-0114-T | AL487: -2 | AM487: 9293-0036-T | AN487: -2
B488: 9941-0098-T | C488: -1 | J488: FAC0785 | K488: -15.0001 | L488: 9330-0001-T | M488: -28 | O488: 9293-0068-001-T | P488: -1 | Q488: 9745-0011-T | R488: -20 | S488: 9941-0084-T | T488: -1 | U488: 9745-0003-T | V488: -6 | W488: 9941-0071-T | X488: -22 | Y488: RAA-0382 | Z488: -1 | AC488: 9968-0020-001-T | AD488: -36 | AE488: 9758-0015-T | AF488: -4 | AG488: 9671-0021-T | AH488: -106 | AI488: 9442-0019-T | AJ488: -5 | AK488: 9594-0012-002-T | AL488: -2 | AM488: 9293-0037-LB | AN488: -40
B489: 9941-0112-T | C489: -1 | J489: FAC0786 | K489: -2 | L489: 9330-0002-T | M489: -23 | O489: 9325-0001 | P489: -900 | Q489: 9747-0001-T | R489: -80 | S489: 9941-0098-T | T489: -1 | U489: 9745-0011-T | V489: -30 | W489: 9941-0092-T | X489: -1 | Y489: RAA-0401 | Z489: -0.1 | AC489: 9968-0045-T | AD489: -27 | AE489: 9869-0003-T | AF489: -18 | AG489: 9672-0003-T | AH489: -1 | AI489: 9473-0015-T | AJ489: -1 | AK489: 9595-0006-T | AL489: -1 | AM489: 9293-0037-T | AN489: -5
B490: 9941-0136-003-T | C490: -24 | J490: FAC0789 | K490: -27 | L490: 9331-0001-T | M490: -45 | O490: 9326-0008-T | P490: -15 | Q490: 9757-0094-T | R490: -6 | S490: 9941-0101-003-T | T490: -20 | U490: 9754-0007-003-T | V490: -1 | W490: 9941-0136-003-T | X490: -10 | Y490: RAA-0402 | Z490: -0.5 | AC490: AD1021-01 | AD490: -1 | AE490: 9869-0006-052-T | AF490: -4 | AG490: 9674-0010-003-T | AH490: -48 | AI490: 9473-0020-T | AJ490: -8 | AK490: 9599-0023-001-T | AL490: -5 | AM490: 9325-0001 | AN490: -4054.51
B491: 9941-0136-004-T | C491: -32 | J491: FAC0803 | K491: -2 | L491: 9333-0003-T | M491: -855 | O491: 9326-0019-003-T | P491: -2 | Q491: 9757-0096-T | R491: -2 | S491: 9941-0136-003-T | T491: -13 | U491: 9757-0094-T | V491: -9 | W491: 9941-0136-004-T | X491: -16 | Y491: RAA-0413 | Z491: -10 | AC491: CUSDECAL | AD491: -3 | AE491: 9873-0007-T | AF491: -4 | AG491: 9678-0001-T | AH491: -1 | AI491: 9489-0012-001-T | AJ491: -1 | AK491: 9601-0024-001-T | AL491: -17 | AM491: 9326-0019-003-T | AN491: -2
B492: 9941-0177-T | C492: -14 | J492: FAC0812 | K492: -2 | L492: 9333-0008-T | M492: -16 | O492: 9326-0043-002-T | P492: -192 | Q492: 9758-0002-001-T | R492: -12 | S492: 9941-0136-004-T | T492: -40 | U492: 9757-0096-T | V492: -3 | W492: 9941-0157-T | X492: -1 | Y492: RAA-0416 | Z492: -2 | AC492: ESP0001 | AD492: -9 | AE492: 9874-0031-T | AF492: -156 | AG492: 9678-0005-T | AH492: -132 | AI492: 9489-0029-T | AJ492: -1 | AK492: 9601-0039-T | AL492: -2 | AM492: 9326-0030-001-T | AN492: -2
B493: 9941-0196-T | C493: -1 | J493: FAC0813 | K493: -1 | L493: 9334-0008-003-T | M493: -17 | O493: 9326-0046-002-T | P493: -13 | Q493: 9758-0007-T | R493: -8 | S493: 9941-0177-T | T493: -9 | U493: 9757-0146-T | V493: -1 | W493: 9941-0177-T | X493: -6 | Y493: RAE-0109 | Z493: -152.16 | AC493: FAC0007 | AD493: -2 | AE493: 9880-0020-T | AF493: -6 | AG493: 9681-0001-T | AH493: -8 | AI493: 9489-0032-T | AJ493: -2 | AK493: 9667-0002-002-T | AL493: -6 | AM493: 9326-0043-001-T | AN493: -18
B494: 9941-0231-001-T | C494: -8 | J494: FAC1099 | K494: -2 | L494: 9334-0008-005-T | M494: -34 | O494: 9326-0047-002-T | P494: -15 | Q494: 9758-0015-T | R494: -14 | S494: 9941-0209-T | T494: -6 | U494: 9758-0007-T | V494: -7 | W494: 9941-0209-T | X494: -10 | Y494: RAF-0101 | Z494: -24 | AC494: FAC0013 | AD494: -12 | AE494: 9880-0022-007-T | AF494: -60 | AG494: 9728-0045-T | AH494: -36 | AI494: 9489-0033-001-T | AJ494: -8 | AK494: 9667-0002-004-T | AL494: -2 | AM494: 9326-0043-002-T | AN494: -55
B495: 9941-0231-003-T | C495: -32 | J495: FAC1163 | K495: -3 | L495: 9379-0018-T | M495: -3 | O495: 9326-0048-002-T | P495: -15 | Q495: 9873-0007-T | R495: -8 | S495: 9941-0223 | T495: -19 | U495: 9758-0015-T | V495: -4 | W495: 9941-0210-002-T | X495: -3 | Y495: RAF-0102 | Z495: -388.66 | AC495: FAC0014 | AD495: -44 | AE495: 9880-0022-008-T | AF495: -60 | AG495: 9728-0061-T | AH495: -5 | AI495: 9489-0046-T | AJ495: -1 | AK495: 9667-0002-005-T | AL495: -9 | AM495: 9326-0045-001-T | AN495: -9
B496: 9941-0235-T | C496: -9 | J496: FST-0114 | K496: -300 | L496: 9379-0020-T | M496: -3 | O496: 9326-0059-002-T | P496: -8 | Q496: 9874-0031-T | R496: -1 | S496: 9941-0231-003-T | T496: -9 | U496: 9869-0003-T | V496: -6 | W496: 9941-0213-002-T | X496: -1 | Y496: RAF-0103 | Z496: -21 | AC496: FAC0023 | AD496: -5 | AE496: 9880-0022-018-t | AF496: -8 | AG496: 9733-0001-T | AH496: -1 | AI496: 9489-0062-007-T | AJ496: -2 | AK496: 9669-0005-T | AL496: -1 | AM496: 9326-0045-002-T | AN496: -3
B497: 9941-0239-T | C497: -16 | J497: FST-0138 | K497: -350 | L497: 9384-0003-001-T | M497: -69 | O497: 9326-0060-T | P497: -17 | Q497: 9874-0033-T | R497: -35 | S497: 9941-0239-T | T497: -10 | U497: 9873-0007-T | V497: -4 | W497: 9941-0223 | X497: -17 | Y497: RAF-0104 | Z497: -0.13 | AC497: FAC0120 | AD497: -35 | AE497: 9880-0037-T | AF497: -71 | AG497: 9738-0001-T | AH497: -72 | AI497: 9489-0064-002-T | AJ497: -7 | AK497: 9669-0007-001-T | AL497: -18 | AM497: 9326-0046-002-T | AN497: -16
B498: 9941-0256-T | C498: -8 | J498: FST-0288 | K498: -200 | L498: 9387-0003-t | M498: -16 | O498: 9326-0071-002-T | P498: -4 | Q498: 9874-0037-001-T | R498: -39 | S498: 9941-0259-003-T | T498: -6 | U498: 9874-0031-T | V498: -13 | W498: 9941-0231-003-T | X498: -12 | Y498: RAF-0106 | Z498: -33.275 | AC498: FAC0121 | AD498: -20 | AE498: 9880-0045-T | AF498: -6.84 | AG498: 9739-0001-T | AH498: -52 | AI498: 9489-0066-T | AJ498: -122 | AK498: 9669-0009-001-T | AL498: -2 | AM498: 9326-0047-002-T | AN498: -6
...

Sheet Fore
A1: Item | B1: Item Description | C1: 45658 | D1: 45689 | E1: 45717 | F1: 45748 | G1: 45778 | H1: 45809 | I1: 45839 | J1: 45870 | K1: 45901 | L1: 45931 | M1: 45962 | N1: 45992 | O1: 46023 | P1: 46054 | Q1: 46082 | R1: 46113 | S1: 46143 | T1: 46174 | U1: Total | V1: Avg. usage n18 | W1: Dairy Uage | X1: Total% | Y1: Cum% | Z1: cv% | AA1: Group | AB1: Group | AC1: Match
A2: FST-0305 | B2: M10 WASHER SS | C2: 0 | D2: 0 | E2: 0 | F2: 3000 | G2: 4430 | H2: 4821 | I2: 8080 | J2: 12241 | K2: 7900 | L2: 2224 | M2: 3836 | N2: 150 | O2: 1200 | P2: 4014 | Q2: 5677 | R2: 3489 | S2: 9050 | T2: 3450 | U2: =SUM(C2:T2) -> 73562 | V2: =AVERAGE(C2:T2) -> 4904.1333 | W2: =V2/30 -> 163.47111 | X2: =U2/SUM($U$2:$U$410) -> 0.11114376 | Y2: =X2 -> 0.11114376 | Z2: =_xlfn.STDEV.P(C2:T2)/AVERAGE(C2:T2) -> 0.6319878 | AA2: =IF(Y2<=0.7,"A",IF(Y2<=0.9,"B","C")) -> A | AB2: =IF(Z2<=0.5,"X",IF(Z2<=1,"Y","Z")) -> Y | AC2: =AA2&AB2 -> AY
A3: FAC0465 | B3: CABLE TIE REMOVE SIZ11-12" W4.5-4.8mm BK | C3: 0 | D3: 0 | E3: 0 | F3: 4300 | G3: 1005 | H3: 3200 | I3: 7800 | J3: 7894 | K3: 8183 | L3: 4000 | M3: 3738 | N3: 200 | O3: 1900 | P3: 3885.75 | Q3: 3966 | R3: 3204.999 | S3: 5798.333 | T3: 1100.667 | U3: =SUM(C3:T3) -> 60175.749 | V3: =AVERAGE(C3:T3) -> 4011.7166 | W3: =V3/30 -> 133.72389 | X3: =U3/SUM($U$2:$U$410) -> 0.090918665 | Y3: =X3+Y2 -> 0.20206242 | Z3: =_xlfn.STDEV.P(C3:T3)/AVERAGE(C3:T3) -> 0.60377427 | AA3: =IF(Y3<=0.7,"A",IF(Y3<=0.9,"B","C")) -> A | AB3: =IF(Z3<=0.5,"X",IF(Z3<=1,"Y","Z")) -> Y | AC3: =AA3&AB3 -> AY
A4: FST-0298 | B4: M8 FLAT WASHER SS | C4: 0 | D4: 0 | E4: 0 | F4: 1580 | G4: 700 | H4: 2473.3336 | I4: 3777.5 | J4: 4183.5 | K4: 2838.5 | L4: 1850 | M4: 2758 | N4: 392 | O4: 1000 | P4: 3933 | Q4: 5067 | R4: 4510 | S4: 9100 | T4: 1678 | U4: =SUM(C4:T4) -> 45840.834 | V4: =AVERAGE(C4:T4) -> 3056.0556 | W4: =V4/30 -> 101.86852 | X4: =U4/SUM($U$2:$U$410) -> 0.06926025 | Y4: =X4+Y3 -> 0.27132267 | Z4: =_xlfn.STDEV.P(C4:T4)/AVERAGE(C4:T4) -> 0.69737562 | AA4: =IF(Y4<=0.7,"A",IF(Y4<=0.9,"B","C")) -> A | AB4: =IF(Z4<=0.5,"X",IF(Z4<=1,"Y","Z")) -> Y | AC4: =AA4&AB4 -> AY
A5: 9965-0009-T | B5: FLAT WASHER M16 CLASS10 ZINC PLATED | C5: 2862 | D5: 3150 | E5: 3200.0008 | F5: 656 | G5: 1183 | H5: 2149.0001 | I5: 3138.9999 | J5: 6278 | K5: 3600 | L5: 4162 | M5: 3100 | N5: 100 | O5: 1500 | P5: 800 | Q5: 2015 | R5: 3132 | S5: 2732 | T5: 1945 | U5: =SUM(C5:T5) -> 45703.001 | V5: =AVERAGE(C5:T5) -> 2539.0556 | W5: =V5/30 -> 84.635187 | X5: =U5/SUM($U$2:$U$410) -> 0.069052 | Y5: =X5+Y4 -> 0.34037467 | Z5: =_xlfn.STDEV.P(C5:T5)/AVERAGE(C5:T5) -> 0.55647686 | AA5: =IF(Y5<=0.7,"A",IF(Y5<=0.9,"B","C")) -> A | AB5: =IF(Z5<=0.5,"X",IF(Z5<=1,"Y","Z")) -> Y | AC5: =AA5&AB5 -> AY
A6: FST-0291 | B6: M6 WASHER SS | C6: 0 | D6: 0 | E6: 0 | F6: 1400 | G6: 3046 | H6: 1080 | I6: 6007 | J6: 6513 | K6: 6345.4445 | L6: 3657 | M6: 2000 | N6: 0 | O6: 2200 | P6: 2416 | Q6: 3200 | R6: 3000 | S6: 2192 | T6: 200 | U6: =SUM(C6:T6) -> 43256.444 | V6: =AVERAGE(C6:T6) -> 3089.746 | W6: =V6/30 -> 102.99153 | X6: =U6/SUM($U$2:$U$410) -> 0.065355534 | Y6: =X6+Y5 -> 0.40573021 | Z6: =_xlfn.STDEV.P(C6:T6)/AVERAGE(C6:T6) -> 0.6095389 | AA6: =IF(Y6<=0.7,"A",IF(Y6<=0.9,"B","C")) -> A | AB6: =IF(Z6<=0.5,"X",IF(Z6<=1,"Y","Z")) -> Y | AC6: =AA6&AB6 -> AY
A7: FST-0304 | B7: M10-1.5 HH LOCK NUT SS | C7: 0 | D7: 0 | E7: 0 | F7: 950 | G7: 2950 | H7: 2126 | I7: 4320.3333 | J7: 5769 | K7: 4400.5 | L7: 4337 | M7: 3200 | N7: 0 | O7: 50 | P7: 2085.79 | Q7: 1235 | R7: 2499 | S7: 3169 | T7: 1550 | U7: =SUM(C7:T7) -> 38641.623 | V7: =AVERAGE(C7:T7) -> 2760.1159 | W7: =V7/30 -> 92.003865 | X7: =U7/SUM($U$2:$U$410) -> 0.058383068 | Y7: =X7+Y6 -> 0.46411327 | Z7: =_xlfn.STDEV.P(C7:T7)/AVERAGE(C7:T7) -> 0.55115107 | AA7: =IF(Y7<=0.7,"A",IF(Y7<=0.9,"B","C")) -> A | AB7: =IF(Z7<=0.5,"X",IF(Z7<=1,"Y","Z")) -> Y | AC7: =AA7&AB7 -> AY
A8: FST-0290 | B8: M6 x1.00 LOCKNUT SS | C8: 0 | D8: 0 | E8: 0 | F8: 800.6664 | G8: 1000 | H8: 1000 | I8: 2200.3336 | J8: 5488 | K8: 4694.4445 | L8: 1530 | M8: 339 | N8: 0 | O8: 0 | P8: 1220 | Q8: 1500 | R8: 2280 | S8: 428.571 | T8: 1099.429 | U8: =SUM(C8:T8) -> 23580.445 | V8: =AVERAGE(C8:T8) -> 1813.8803 | W8: =V8/30 -> 60.462678 | X8: =U8/SUM($U$2:$U$410) -> 0.035627351 | Y8: =X8+Y7 -> 0.49974063 | Z8: =_xlfn.STDEV.P(C8:T8)/AVERAGE(C8:T8) -> 0.83261158 | AA8: =IF(Y8<=0.7,"A",IF(Y8<=0.9,"B","C")) -> A | AB8: =IF(Z8<=0.5,"X",IF(Z8<=1,"Y","Z")) -> Y | AC8: =AA8&AB8 -> AY
A9: FST-0297 | B9: M8-1.25 LOCKNUT SS | C9: 0 | D9: 0 | E9: 0 | F9: 800 | G9: 66.6668 | H9: 1853.3334 | I9: 2120.9998 | J9: 2600 | K9: 1900 | L9: 1030 | M9: 917 | N9: 150 | O9: 400 | P9: 2500 | Q9: 1100 | R9: 2733 | S9: 4136 | T9: 50 | U9: =SUM(C9:T9) -> 22357 | V9: =AVERAGE(C9:T9) -> 1490.4667 | W9: =V9/30 -> 49.682222 | X9: =U9/SUM($U$2:$U$410) -> 0.033778867 | Y9: =X9+Y8 -> 0.53351949 | Z9: =_xlfn.STDEV.P(C9:T9)/AVERAGE(C9:T9) -> 0.76983066 | AA9: =IF(Y9<=0.7,"A",IF(Y9<=0.9,"B","C")) -> A | AB9: =IF(Z9<=0.5,"X",IF(Z9<=1,"Y","Z")) -> Y | AC9: =AA9&AB9 -> AY
A10: FST-0311 | B10: M12 WASHER SS | C10: 0 | D10: 0 | E10: 0 | F10: 1100 | G10: 1500.0002 | H10: 1689.9998 | I10: 1260 | J10: 2421 | K10: 1532 | L10: 3266 | M10: 318 | N10: 0 | O10: 1116 | P10: 1957.15 | Q10: 772 | R10: 2228 | S10: 2150 | T10: 0 | U10: =SUM(C10:T10) -> 21310.15 | V10: =AVERAGE(C10:T10) -> 1639.2423 | W10: =V10/30 -> 54.64141 | X10: =U10/SUM($U$2:$U$410) -> 0.032197196 | Y10: =X10+Y9 -> 0.56571669 | Z10: =_xlfn.STDEV.P(C10:T10)/AVERAGE(C10:T10) -> 0.45417521 | AA10: =IF(Y10<=0.7,"A",IF(Y10<=0.9,"B","C")) -> A | AB10: =IF(Z10<=0.5,"X",IF(Z10<=1,"Y","Z")) -> X | AC10: =AA10&AB10 -> AX
A11: 9562-0014-T | B11: M16x2.0 DIN 980 Class 10 Zinc Lock Nut | C11: 3400 | D11: 300 | E11: 1868 | F11: 24 | G11: 305 | H11: 880 | I11: 1690.0001 | J11: 927.9999 | K11: 1500 | L11: 1700 | M11: 200 | N11: 100 | O11: 500 | P11: 43 | Q11: 260 | R11: 1367 | S11: 1750 | T11: 450 | U11: =SUM(C11:T11) -> 17265 | V11: =AVERAGE(C11:T11) -> 959.16667 | W11: =V11/30 -> 31.972222 | X11: =U11/SUM($U$2:$U$410) -> 0.026085438 | Y11: =X11+Y10 -> 0.59180213 | Z11: =_xlfn.STDEV.P(C11:T11)/AVERAGE(C11:T11) -> 0.91312968 | AA11: =IF(Y11<=0.7,"A",IF(Y11<=0.9,"B","C")) -> A | AB11: =IF(Z11<=0.5,"X",IF(Z11<=1,"Y","Z")) -> Y | AC11: =AA11&AB11 -> AY
A12: FST-0301 | B12: M10-1.5 HH Bolt x 40 Lg. SS | C12: 0 | D12: 0 | E12: 0 | F12: 529.9994 | G12: 800 | H12: 860 | I12: 1550 | J12: 1059 | K12: 894 | L12: 661 | M12: 655 | N12: 80 | O12: 340 | P12: 1420 | Q12: 650 | R12: 2090 | S12: 1600 | T12: 240 | U12: =SUM(C12:T12) -> 13428.999 | V12: =AVERAGE(C12:T12) -> 895.26663 | W12: =V12/30 -> 29.842221 | X12: =U12/SUM($U$2:$U$410) -> 0.02028968 | Y12: =X12+Y11 -> 0.61209181 | Z12: =_xlfn.STDEV.P(C12:T12)/AVERAGE(C12:T12) -> 0.60315347 | AA12: =IF(Y12<=0.7,"A",IF(Y12<=0.9,"B","C")) -> A | AB12: =IF(Z12<=0.5,"X",IF(Z12<=1,"Y","Z")) -> Y | AC12: =AA12&AB12 -> AY
A13: FST-0310 | B13: M12-1.75 LOCKNUT SS | C13: 0 | D13: 0 | E13: 0 | F13: 700 | G13: 200 | H13: 874 | I13: 640 | J13: 1239.5461 | K13: 1200.4539 | L13: 1706 | M13: 596 | N13: 0 | O13: 300 | P13: 1607.72 | Q13: 650 | R13: 1240 | S13: 1175 | T13: 39 | U13: =SUM(C13:T13) -> 12167.72 | V13: =AVERAGE(C13:T13) -> 869.12286 | W13: =V13/30 -> 28.970762 | X13: =U13/SUM($U$2:$U$410) -> 0.018384031 | Y13: =X13+Y12 -> 0.63047584 | Z13: =_xlfn.STDEV.P(C13:T13)/AVERAGE(C13:T13) -> 0.5660514 | AA13: =IF(Y13<=0.7,"A",IF(Y13<=0.9,"B","C")) -> A | AB13: =IF(Z13<=0.5,"X",IF(Z13<=1,"Y","Z")) -> Y | AC13: =AA13&AB13 -> AY
A14: FST-0356 | B14: M4 WASHER SS304 | C14: 0 | D14: 0 | E14: 0 | F14: 0 | G14: 0 | H14: 900.0003 | I14: 2233.3351 | J14: 0 | K14: 2366.6646 | L14: 1000 | M14: 0 | N14: 0 | O14: 0 | P14: 1000 | Q14: 1000 | R14: 1000 | S14: 1142 | T14: 0 | U14: =SUM(C14:T14) -> 10642 | V14: =AVERAGE(C14:T14) -> 1182.4444 | W14: =V14/30 -> 39.414815 | X14: =U14/SUM($U$2:$U$410) -> 0.016078843 | Y14: =X14+Y13 -> 0.64655468 | Z14: =_xlfn.STDEV.P(C14:T14)/AVERAGE(C14:T14) -> 0.57216209 | AA14: =IF(Y14<=0.7,"A",IF(Y14<=0.9,"B","C")) -> A | AB14: =IF(Z14<=0.5,"X",IF(Z14<=1,"Y","Z")) -> Y | AC14: =AA14&AB14 -> AY
A15: FST-0312 | B15: M10-1.5 NUT SS | C15: 0 | D15: 0 | E15: 0 | F15: 0 | G15: 315 | H15: 460 | I15: 295 | J15: 1715.3332 | K15: 800 | L15: 3386 | M15: 1473 | N15: 0 | O15: 100 | P15: 0 | Q15: 350 | R15: 900 | S15: 49.9991 | T15: 168.0009 | U15: =SUM(C15:T15) -> 10012.333 | V15: =AVERAGE(C15:T15) -> 834.3611 | W15: =V15/30 -> 27.812037 | X15: =U15/SUM($U$2:$U$410) -> 0.015127489 | Y15: =X15+Y14 -> 0.66168217 | Z15: =_xlfn.STDEV.P(C15:T15)/AVERAGE(C15:T15) -> 1.106837 | AA15: =IF(Y15<=0.7,"A",IF(Y15<=0.9,"B","C")) -> A | AB15: =IF(Z15<=0.5,"X",IF(Z15<=1,"Y","Z")) -> Z | AC15: =AA15&AB15 -> AZ
A16: FST-0337 | B16: M10 - 1.5 HH BOLT x 30mmLG SS | C16: 0 | D16: 0 | E16: 0 | F16: 397 | G16: 938 | H16: 425 | I16: 449 | J16: 1955 | K16: 1724 | L16: 10 | M16: 466 | N16: 133 | O16: 50 | P16: 786 | Q16: 390 | R16: 480 | S16: 1160 | T16: 510 | U16: =SUM(C16:T16) -> 9873 | V16: =AVERAGE(C16:T16) -> 658.2 | W16: =V16/30 -> 21.94 | X16: =U16/SUM($U$2:$U$410) -> 0.014916972 | Y16: =X16+Y15 -> 0.67659914 | Z16: =_xlfn.STDEV.P(C16:T16)/AVERAGE(C16:T16) -> 0.83758158 | AA16: =IF(Y16<=0.7,"A",IF(Y16<=0.9,"B","C")) -> A | AB16: =IF(Z16<=0.5,"X",IF(Z16<=1,"Y","Z")) -> Y | AC16: =AA16&AB16 -> AY
A17: FST-0286 | B17: M6-1.00 HH Bolt x 25 Lg. SS | C17: 0 | D17: 0 | E17: 0 | F17: 0 | G17: 100 | H17: 0 | I17: 2200 | J17: 1104 | K17: 2640 | L17: 829 | M17: 200 | N17: 0 | O17: 0 | P17: 800 | Q17: 400 | R17: 800 | S17: 0 | T17: 0 | U17: =SUM(C17:T17) -> 9073 | V17: =AVERAGE(C17:T17) -> 1008.1111 | W17: =V17/30 -> 33.603704 | X17: =U17/SUM($U$2:$U$410) -> 0.013708264 | Y17: =X17+Y16 -> 0.69030741 | Z17: =_xlfn.STDEV.P(C17:T17)/AVERAGE(C17:T17) -> 0.81390393 | AA17: =IF(Y17<=0.7,"A",IF(Y17<=0.9,"B","C")) -> A | AB17: =IF(Z17<=0.5,"X",IF(Z17<=1,"Y","Z")) -> Y | AC17: =AA17&AB17 -> AY
A18: FST-0300 | B18: M10-1.5 HH Bolt x 35 Lg. SS | C18: 0 | D18: 0 | E18: 0 | F18: 101 | G18: 115 | H18: 540 | I18: 1340 | J18: 1471 | K18: 1160 | L18: 400 | M18: 591 | N18: 0 | O18: 0 | P18: 900 | Q18: 262 | R18: 1060 | S18: 300 | T18: 706 | U18: =SUM(C18:T18) -> 8946 | V18: =AVERAGE(C18:T18) -> 688.15385 | W18: =V18/30 -> 22.938462 | X18: =U18/SUM($U$2:$U$410) -> 0.013516382 | Y18: =X18+Y17 -> 0.70382379 | Z18: =_xlfn.STDEV.P(C18:T18)/AVERAGE(C18:T18) -> 0.64533492 | AA18: =IF(Y18<=0.7,"A",IF(Y18<=0.9,"B","C")) -> B | AB18: =IF(Z18<=0.5,"X",IF(Z18<=1,"Y","Z")) -> Y | AC18: =AA18&AB18 -> BY
A19: FST-0379 | B19: M16x2.0 LOCK NUT PLATED GRADE 8.8 | C19: 0 | D19: 0 | E19: 0 | F19: 398 | G19: 200 | H19: 500.0002 | I19: 1001.9998 | J19: 1060 | K19: 999.9984 | L19: 1410 | M19: 855 | N19: 0 | O19: 550 | P19: 350 | Q19: 300 | R19: 24 | S19: 0 | T19: 1111 | U19: =SUM(C19:T19) -> 8759.9984 | V19: =AVERAGE(C19:T19) -> 673.84603 | W19: =V19/30 -> 22.461534 | X19: =U19/SUM($U$2:$U$410) -> 0.013235354 | Y19: =X19+Y18 -> 0.71705914 | Z19: =_xlfn.STDEV.P(C19:T19)/AVERAGE(C19:T19) -> 0.60240867 | AA19: =IF(Y19<=0.7,"A",IF(Y19<=0.9,"B","C")) -> B | AB19: =IF(Z19<=0.5,"X",IF(Z19<=1,"Y","Z")) -> Y | AC19: =AA19&AB19 -> BY
A20: FST-0293 | B20: M8-1.25 HH Bolt x 25 Lg. SS | C20: 0 | D20: 0 | E20: 0 | F20: 0 | G20: 1000 | H20: 0 | I20: 840 | J20: 1487 | K20: 870 | L20: 50 | M20: 400 | N20: 50 | O20: 250 | P20: 750 | Q20: 750 | R20: 1000 | S20: 850 | T20: 228 | U20: =SUM(C20:T20) -> 8525 | V20: =AVERAGE(C20:T20) -> 655.76923 | W20: =V20/30 -> 21.858974 | X20: =U20/SUM($U$2:$U$410) -> 0.012880299 | Y20: =X20+Y19 -> 0.72993944 | Z20: =_xlfn.STDEV.P(C20:T20)/AVERAGE(C20:T20) -> 0.62877472 | AA20: =IF(Y20<=0.7,"A",IF(Y20<=0.9,"B","C")) -> B | AB20: =IF(Z20<=0.5,"X",IF(Z20<=1,"Y","Z")) -> Y | AC20: =AA20&AB20 -> BY
A21: FST-0295 | B21: M8-1.25 HH Bolt x 30 Lg. SS | C21: 0 | D21: 0 | E21: 0 | F21: 1000 | G21: 733 | H21: 720 | I21: 300 | J21: 1559 | K21: 960 | L21: 116 | M21: 300 | N21: 100 | O21: 80 | P21: 1004 | Q21: 300 | R21: 0 | S21: 1000 | T21: 230 | U21: =SUM(C21:T21) -> 8402 | V21: =AVERAGE(C21:T21) -> 600.14286 | W21: =V21/30 -> 20.004762 | X21: =U21/SUM($U$2:$U$410) -> 0.01269446 | Y21: =X21+Y20 -> 0.7426339 | Z21: =_xlfn.STDEV.P(C21:T21)/AVERAGE(C21:T21) -> 0.73528474 | AA21: =IF(Y21<=0.7,"A",IF(Y21<=0.9,"B","C")) -> B | AB21: =IF(Z21<=0.5,"X",IF(Z21<=1,"Y","Z")) -> Y | AC21: =AA21&AB21 -> BY
A22: 047-2127-003 | B22: 5/8 HUCK BOLT 0.75-1GP (C50LR-BR20-12GA) | C22: 944 | D22: 1080 | E22: 463 | F22: 0 | G22: 330 | H22: 0 | I22: 440 | J22: 231 | K22: 550 | L22: 0 | M22: 200 | N22: 42 | O22: 110 | P22: 220 | Q22: 330 | R22: 570 | S22: 630 | T22: 0 | U22: =SUM(C22:T22) -> 6140 | V22: =AVERAGE(C22:T22) -> 438.57143 | W22: =V22/30 -> 14.619048 | X22: =U22/SUM($U$2:$U$410) -> 0.0092768369 | Y22: =X22+Y21 -> 0.75191074 | Z22: =_xlfn.STDEV.P(C22:T22)/AVERAGE(C22:T22) -> 0.65926963 | AA22: =IF(Y22<=0.7,"A",IF(Y22<=0.9,"B","C")) -> B | AB22: =IF(Z22<=0.5,"X",IF(Z22<=1,"Y","Z")) -> Y | AC22: =AA22&AB22 -> BY
A23: FAC0548 | B23: BLIND RIVET SS DIA3.2X9.6mm. No.4-4 | C23: 0 | D23: 0 | E23: 0 | F23: 0 | G23: 1000 | H23: 0 | I23: 1000 | J23: 0 | K23: 0 | L23: 1000 | M23: 0 | N23: 0 | O23: 500 | P23: 1222.22 | Q23: 0 | R23: 1000 | S23: 0 | T23: 0 | U23: =SUM(C23:T23) -> 5722.22 | V23: =AVERAGE(C23:T23) -> 817.46 | W23: =V23/30 -> 27.248667 | X23: =U23/SUM($U$2:$U$410) -> 0.0086456191 | Y23: =X23+Y22 -> 0.76055636 | Z23: =_xlfn.STDEV.P(C23:T23)/AVERAGE(C23:T23) -> 0.47740914 | AA23: =IF(Y23<=0.7,"A",IF(Y23<=0.9,"B","C")) -> B | AB23: =IF(Z23<=0.5,"X",IF(Z23<=1,"Y","Z")) -> X | AC23: =AA23&AB23 -> BX
A24: FST-0475 | B24: SELF DRILLING SCREW 1" SUS#8X1" JP | C24: 0 | D24: 0 | E24: 0 | F24: 0 | G24: 0 | H24: 0 | I24: 1667 | J24: 0 | K24: 0 | L24: 1000 | M24: 0 | N24: 0 | O24: 0 | P24: 0 | Q24: 1000 | R24: 0 | S24: 1000 | T24: 1000 | U24: =SUM(C24:T24) -> 5667 | V24: =AVERAGE(C24:T24) -> 944.5 | W24: =V24/30 -> 31.483333 | X24: =U24/SUM($U$2:$U$410) -> 0.008562188 | Y24: =X24+Y23 -> 0.76911855 | Z24: =_xlfn.STDEV.P(C24:T24)/AVERAGE(C24:T24) -> 0.51623116 | AA24: =IF(Y24<=0.7,"A",IF(Y24<=0.9,"B","C")) -> B | AB24: =IF(Z24<=0.5,"X",IF(Z24<=1,"Y","Z")) -> Y | AC24: =AA24&AB24 -> BY
A25: FAC0642 | B25: CABLE TIE SIZE 14 1/2" xWide7.6 mm BLACK | C25: 0 | D25: 0 | E25: 0 | F25: 0 | G25: 600 | H25: 100 | I25: 0 | J25: 470 | K25: 300 | L25: 600 | M25: 330 | N25: 0 | O25: 100 | P25: 728.55 | Q25: 600 | R25: 300 | S25: 880 | T25: 100 | U25: =SUM(C25:T25) -> 5108.55 | V25: =AVERAGE(C25:T25) -> 425.7125 | W25: =V25/30 -> 14.190417 | X25: =U25/SUM($U$2:$U$410) -> 0.007718434 | Y25: =X25+Y24 -> 0.77683698 | Z25: =_xlfn.STDEV.P(C25:T25)/AVERAGE(C25:T25) -> 0.58733359 | AA25: =IF(Y25<=0.7,"A",IF(Y25<=0.9,"B","C")) -> B | AB25: =IF(Z25<=0.5,"X",IF(Z25<=1,"Y","Z")) -> Y | AC25: =AA25&AB25 -> BY
A26: FST-0390 | B26: NUT STUD SS. SIZE 1/2" - 13 NC | C26: 0 | D26: 0 | E26: 0 | F26: 0 | G26: 500 | H26: 260 | I26: 0 | J26: 500 | K26: 500 | L26: 0 | M26: 0 | N26: 128 | O26: 500 | P26: 500 | Q26: 500 | R26: 0 | S26: 500 | T26: 1111 | U26: =SUM(C26:T26) -> 4999 | V26: =AVERAGE(C26:T26) -> 454.45455 | W26: =V26/30 -> 15.148485 | X26: =U26/SUM($U$2:$U$410) -> 0.0075529165 | Y26: =X26+Y25 -> 0.7843899 | Z26: =_xlfn.STDEV.P(C26:T26)/AVERAGE(C26:T26) -> 0.59211011 | AA26: =IF(Y26<=0.7,"A",IF(Y26<=0.9,"B","C")) -> B | AB26: =IF(Z26<=0.5,"X",IF(Z26<=1,"Y","Z")) -> Y | AC26: =AA26&AB26 -> BY
A27: FST-0367 | B27: 1/2" SPRING WASHER SS304 | C27: 0 | D27: 0 | E27: 0 | F27: 0 | G27: 500 | H27: 500 | I27: 0 | J27: 187 | K27: 500 | L27: 0 | M27: 0 | N27: 0 | O27: 600 | P27: 100 | Q27: 500 | R27: 1000 | S27: 0 | T27: 1111 | U27: =SUM(C27:T27) -> 4998 | V27: =AVERAGE(C27:T27) -> 499.8 | W27: =V27/30 -> 16.66 | X27: =U27/SUM($U$2:$U$410) -> 0.0075514056 | Y27: =X27+Y26 -> 0.7919413 | Z27: =_xlfn.STDEV.P(C27:T27)/AVERAGE(C27:T27) -> 0.67592993 | AA27: =IF(Y27<=0.7,"A",IF(Y27<=0.9,"B","C")) -> B | AB27: =IF(Z27<=0.5,"X",IF(Z27<=1,"Y","Z")) -> Y | AC27: =AA27&AB27 -> BY
A28: FST-0332 | B28: M10-1.5 BOTTON HEAD SOCKET x 30mm LG. SS | C28: 0 | D28: 0 | E28: 0 | F28: 200 | G28: 300 | H28: 200 | I28: 500 | J28: 1190 | K28: 600 | L28: 0 | M28: 300 | N28: 0 | O28: 0 | P28: 642.9 | Q28: 0 | R28: 700 | S28: 160 | T28: 200 | U28: =SUM(C28:T28) -> 4992.9 | V28: =AVERAGE(C28:T28) -> 453.9 | W28: =V28/30 -> 15.13 | X28: =U28/SUM($U$2:$U$410) -> 0.0075437001 | Y28: =X28+Y27 -> 0.799485 | Z28: =_xlfn.STDEV.P(C28:T28)/AVERAGE(C28:T28) -> 0.66051884 | AA28: =IF(Y28<=0.7,"A",IF(Y28<=0.9,"B","C")) -> B | AB28: =IF(Z28<=0.5,"X",IF(Z28<=1,"Y","Z")) -> Y | AC28: =AA28&AB28 -> BY
A29: FAC0380 | B29: SELF DRILLING HEX WASHER NO.14x1" | C29: 0 | D29: 0 | E29: 0 | F29: 444 | G29: 0 | H29: 0 | I29: 900 | J29: 800 | K29: 0 | L29: 700 | M29: 483 | N29: 0 | O29: 0 | P29: 1000 | Q29: 0 | R29: 564 | S29: 0 | T29: 0 | U29: =SUM(C29:T29) -> 4891 | V29: =AVERAGE(C29:T29) -> 698.71429 | W29: =V29/30 -> 23.290476 | X29: =U29/SUM($U$2:$U$410) -> 0.0073897409 | Y29: =X29+Y28 -> 0.80687474 | Z29: =_xlfn.STDEV.P(C29:T29)/AVERAGE(C29:T29) -> 0.28165902 | AA29: =IF(Y29<=0.7,"A",IF(Y29<=0.9,"B","C")) -> B | AB29: =IF(Z29<=0.5,"X",IF(Z29<=1,"Y","Z")) -> X | AC29: =AA29&AB29 -> BX
A30: 9043-0018-055-T | B30: BOLT M16-2.0x55 DIN 931 Class 10.9 Zinc | C30: 425 | D30: 475 | E30: 144.9999 | F30: 0 | G30: 500 | H30: 200 | I30: 365 | J30: 450.0004 | K30: 500.9996 | L30: 1049 | M30: 0 | N30: 0 | O30: 0 | P30: 25 | Q30: 30 | R30: 240 | S30: 205 | T30: 54 | U30: =SUM(C30:T30) -> 4663.9999 | V30: =AVERAGE(C30:T30) -> 310.93333 | W30: =V30/30 -> 10.364444 | X30: =U30/SUM($U$2:$U$410) -> 0.0070467697 | Y30: =X30+Y29 -> 0.81392151 | Z30: =_xlfn.STDEV.P(C30:T30)/AVERAGE(C30:T30) -> 0.85425268 | AA30: =IF(Y30<=0.7,"A",IF(Y30<=0.9,"B","C")) -> B | AB30: =IF(Z30<=0.5,"X",IF(Z30<=1,"Y","Z")) -> Y | AC30: =AA30&AB30 -> BY
A31: 9043-0018-065-T | B31: BOLT M16-2.0x65 DIN 931 Class 10.9 Zinc | C31: 640 | D31: 120 | E31: 300 | F31: 0 | G31: 360 | H31: 400 | I31: 560 | J31: 260.0004 | K31: 770.9996 | L31: 200 | M31: 33.33 | N31: 0 | O31: 0 | P31: 0 | Q31: 230 | R31: 170 | S31: 300 | T31: 42 | U31: =SUM(C31:T31) -> 4386.33 | V31: =AVERAGE(C31:T31) -> 313.30929 | W31: =V31/30 -> 10.443643 | X31: =U31/SUM($U$2:$U$410) -> 0.0066272423 | Y31: =X31+Y30 -> 0.82054875 | Z31: =_xlfn.STDEV.P(C31:T31)/AVERAGE(C31:T31) -> 0.67147768 | AA31: =IF(Y31<=0.7,"A",IF(Y31<=0.9,"B","C")) -> B | AB31: =IF(Z31<=0.5,"X",IF(Z31<=1,"Y","Z")) -> Y | AC31: =AA31&AB31 -> BY
A32: FST-0335 | B32: M12 - 1.75 HH BOLT x 45mmLG SS | C32: 0 | D32: 0 | E32: 0 | F32: 80 | G32: 400 | H32: 300 | I32: 510 | J32: 605 | K32: 900 | L32: 0 | M32: 200 | N32: 0 | O32: 0 | P32: 428.55 | Q32: 350 | R32: 300 | S32: 0 | T32: 200 | U32: =SUM(C32:T32) -> 4273.55 | V32: =AVERAGE(C32:T32) -> 388.50455 | W32: =V32/30 -> 12.950152 | X32: =U32/SUM($U$2:$U$410) -> 0.0064568446 | Y32: =X32+Y31 -> 0.8270056 | Z32: =_xlfn.STDEV.P(C32:T32)/AVERAGE(C32:T32) -> 0.55335592 | AA32: =IF(Y32<=0.7,"A",IF(Y32<=0.9,"B","C")) -> B | AB32: =IF(Z32<=0.5,"X",IF(Z32<=1,"Y","Z")) -> Y | AC32: =AA32&AB32 -> BY
A33: FST-0307 | B33: M12-1.75 HH BOLT 40 LG. A2-70 SS304 | C33: 0 | D33: 0 | E33: 0 | F33: 200.6665 | G33: 100.0002 | H33: 200 | I33: 632 | J33: 518 | K33: 481.9998 | L33: 200 | M33: 50 | N33: 0 | O33: 0 | P33: 308.55 | Q33: 518 | R33: 560 | S33: 160 | T33: 0 | U33: =SUM(C33:T33) -> 3929.2165 | V33: =AVERAGE(C33:T33) -> 327.43471 | W33: =V33/30 -> 10.91449 | X33: =U33/SUM($U$2:$U$410) -> 0.0059365962 | Y33: =X33+Y32 -> 0.8329422 | Z33: =_xlfn.STDEV.P(C33:T33)/AVERAGE(C33:T33) -> 0.5907583 | AA33: =IF(Y33<=0.7,"A",IF(Y33<=0.9,"B","C")) -> B | AB33: =IF(Z33<=0.5,"X",IF(Z33<=1,"Y","Z")) -> Y | AC33: =AA33&AB33 -> BY
A34: FST-0318 | B34: M6-1.00 HH BOLT X 16mmLG. SS | C34: 0 | D34: 0 | E34: 0 | F34: 200 | G34: 600 | H34: 0 | I34: 0 | J34: 520 | K34: 387 | L34: 20 | M34: 400 | N34: 0 | O34: 1200 | P34: 0 | Q34: 0 | R34: 0 | S34: 600 | T34: 0 | U34: =SUM(C34:T34) -> 3927 | V34: =AVERAGE(C34:T34) -> 490.875 | W34: =V34/30 -> 16.3625 | X34: =U34/SUM($U$2:$U$410) -> 0.0059332473 | Y34: =X34+Y33 -> 0.83887544 | Z34: =_xlfn.STDEV.P(C34:T34)/AVERAGE(C34:T34) -> 0.66517188 | AA34: =IF(Y34<=0.7,"A",IF(Y34<=0.9,"B","C")) -> B | AB34: =IF(Z34<=0.5,"X",IF(Z34<=1,"Y","Z")) -> Y | AC34: =AA34&AB34 -> BY
A35: FST-0114 | B35: 3/8-16 NC NYLOCK NUT | C35: 0 | D35: 0 | E35: 0 | F35: 300 | G35: 0 | H35: 400 | I35: 0 | J35: 600 | K35: 398 | L35: 700 | M35: 100 | N35: 0 | O35: 0 | P35: 365 | Q35: 200 | R35: 200 | S35: 400 | T35: 0 | U35: =SUM(C35:T35) -> 3663 | V35: =AVERAGE(C35:T35) -> 366.3 | W35: =V35/30 -> 12.21 | X35: =U35/SUM($U$2:$U$410) -> 0.0055343735 | Y35: =X35+Y34 -> 0.84440982 | Z35: =_xlfn.STDEV.P(C35:T35)/AVERAGE(C35:T35) -> 0.47274954 | AA35: =IF(Y35<=0.7,"A",IF(Y35<=0.9,"B","C")) -> B | AB35: =IF(Z35<=0.5,"X",IF(Z35<=1,"Y","Z")) -> X | AC35: =AA35&AB35 -> BX
A36: FAC0398 | B36: CABLE TIE SIZE 20-21 1/16" x W8-8.8mm BK | C36: 0 | D36: 0 | E36: 0 | F36: 100 | G36: 400 | H36: 200 | I36: 220 | J36: 0 | K36: 600 | L36: 200 | M36: 173 | N36: 0 | O36: 100 | P36: 300 | Q36: 400 | R36: 100 | S36: 500 | T36: 0 | U36: =SUM(C36:T36) -> 3293 | V36: =AVERAGE(C36:T36) -> 274.41667 | W36: =V36/30 -> 9.1472222 | X36: =U36/SUM($U$2:$U$410) -> 0.0049753459 | Y36: =X36+Y35 -> 0.84938516 | Z36: =_xlfn.STDEV.P(C36:T36)/AVERAGE(C36:T36) -> 0.58065376 | AA36: =IF(Y36<=0.7,"A",IF(Y36<=0.9,"B","C")) -> B | AB36: =IF(Z36<=0.5,"X",IF(Z36<=1,"Y","Z")) -> Y | AC36: =AA36&AB36 -> BY
A37: FST-0288 | B37: M6-1.00 HH Bolt x 20 Lg. SS | C37: 0 | D37: 0 | E37: 0 | F37: 200 | G37: 500 | H37: 420 | I37: 320 | J37: 895.8343 | K37: 425.1657 | L37: 200 | M37: 200 | N37: 0 | O37: 0 | P37: 0 | Q37: 42 | R37: 0 | S37: 0 | T37: 0 | U37: =SUM(C37:T37) -> 3203 | V37: =AVERAGE(C37:T37) -> 355.88889 | W37: =V37/30 -> 11.862963 | X37: =U37/SUM($U$2:$U$410) -> 0.0048393662 | Y37: =X37+Y36 -> 0.85422453 | Z37: =_xlfn.STDEV.P(C37:T37)/AVERAGE(C37:T37) -> 0.65826389 | AA37: =IF(Y37<=0.7,"A",IF(Y37<=0.9,"B","C")) -> B | AB37: =IF(Z37<=0.5,"X",IF(Z37<=1,"Y","Z")) -> Y | AC37: =AA37&AB37 -> BY
A38: 9043-0069-045-T | C38: 336 | D38: 196 | E38: 256 | F38: 44 | G38: 100 | H38: 84 | I38: 28 | J38: 116 | K38: 272 | L38: 84 | M38: 84 | N38: 178 | O38: 250 | P38: 168 | Q38: 304 | R38: 140 | S38: 332 | T38: 92 | U38: =SUM(C38:T38) -> 3064 | V38: =AVERAGE(C38:T38) -> 170.22222 | W38: =V38/30 -> 5.6740741 | X38: =U38/SUM($U$2:$U$410) -> 0.0046293531 | Y38: =X38+Y37 -> 0.85885388 | Z38: =_xlfn.STDEV.P(C38:T38)/AVERAGE(C38:T38) -> 0.57045725 | AA38: =IF(Y38<=0.7,"A",IF(Y38<=0.9,"B","C")) -> B | AB38: =IF(Z38<=0.5,"X",IF(Z38<=1,"Y","Z")) -> Y | AC38: =AA38&AB38 -> BY
A39: FST-0552 | B39: M6 JP BOLT x 30 mm LG SS304 | C39: 0 | D39: 0 | E39: 0 | F39: 0 | G39: 0 | H39: 0 | I39: 0 | J39: 0 | K39: 555.5556 | L39: 0 | M39: 0 | N39: 0 | O39: 0 | P39: 0 | Q39: 500 | R39: 0 | S39: 0 | T39: 2000 | U39: =SUM(C39:T39) -> 3055.5556 | V39: =AVERAGE(C39:T39) -> 763.8889 | W39: =V39/30 -> 25.462963 | X39: =U39/SUM($U$2:$U$410) -> 0.0046165946 | Y39: =X39+Y38 -> 0.86347048 | Z39: =_xlfn.STDEV.P(C39:T39)/AVERAGE(C39:T39) -> 0.9762468 | AA39: =IF(Y39<=0.7,"A",IF(Y39<=0.9,"B","C")) -> B | AB39: =IF(Z39<=0.5,"X",IF(Z39<=1,"Y","Z")) -> Y | AC39: =AA39&AB39 -> BY
A40: FST-0294 | B40: M8-1.25 HH Bolt x 20 Lg. SS | C40: 0 | D40: 0 | E40: 0 | F40: 0 | G40: 0 | H40: 0 | I40: 262.5 | J40: 1650 | K40: 0 | L40: 0 | M40: 300 | N40: 0 | O40: 0 | P40: 5 | Q40: 800 | R40: 0 | S40: 0 | T40: 0 | U40: =SUM(C40:T40) -> 3017.5 | V40: =AVERAGE(C40:T40) -> 603.5 | W40: =V40/30 -> 20.116667 | X40: =U40/SUM($U$2:$U$410) -> 0.0045590969 | Y40: =X40+Y39 -> 0.86802957 | Z40: =_xlfn.STDEV.P(C40:T40)/AVERAGE(C40:T40) -> 0.96629435 | AA40: =IF(Y40<=0.7,"A",IF(Y40<=0.9,"B","C")) -> B | AB40: =IF(Z40<=0.5,"X",IF(Z40<=1,"Y","Z")) -> Y | AC40: =AA40&AB40 -> BY
...

Sheet Cast
C1: 0.3
A2: Item | B2: Item Description | C2: Match | D2: 45658 | E2: F-Jan25 | F2: 45689 | G2: F-Feb25 | H2: 45717 | I2: F-Mar25 | J2: 45748 | K2: F-Apr25 | L2: 45778 | M2: F-May25 | N2: 45809 | O2: F-Jun25 | P2: 45839 | Q2: F-July25 | R2: 45870 | S2: F-Aug25 | T2: 45901 | U2: F-Sep25 | V2: 45931 | W2: F-JOct25 | X2: 45962 | Y2: F-Nov25 | Z2: 45992 | AA2: F-Dec25 | AB2: 46023 | AC2: F-Jan26 | AD2: 46054 | AE2: F-Feb26 | AF2: 46082 | AG2: F-Mar26 | AH2: 46113 | AI2: F-Apr26 | AJ2: 46143 | AK2: F-May26 | AL2: 46174 | AM2: F-Jun26 | AN2: ae | AO2: ape | AP2: mape
A3: FST-0305 | B3: M10 WASHER SS | C3: =_xlfn.XLOOKUP(A3,Fore!A:A,Fore!AC:AC) -> AY | D3: 0 | E3: =D3 -> 0 | F3: 0 | G3: =$C$1*D3+(1-$C$1)*E3 -> 0 | H3: 0 | I3: =$C$1*F3+(1-$C$1)*G3 -> 0 | J3: 3000 | K3: =$C$1*H3+(1-$C$1)*I3 -> 0 | L3: 4430 | M3: =$C$1*J3+(1-$C$1)*K3 -> 900 | N3: 4821 | O3: =$C$1*M3+(1-$C$1)*L3 -> 3371 | P3: 8080 | Q3: =$C$1*N3+(1-$C$1)*O3 -> 3806 | R3: 12241 | S3: =$C$1*P3+(1-$C$1)*Q3 -> 5088.2 | T3: 7900 | U3: =$C$1*R3+(1-$C$1)*S3 -> 7234.04 | V3: 2224 | W3: =$C$1*T3+(1-$C$1)*U3 -> 7433.828 | X3: 3836 | Y3: =$C$1*V3+(1-$C$1)*W3 -> 5870.8796 | Z3: 150 | AA3: =$C$1*X3+(1-$C$1)*Y3 -> 5260.4157 | AB3: 1200 | AC3: =$C$1*Z3+(1-$C$1)*AA3 -> 3727.291 | AD3: 4014 | AE3: =$C$1*AB3+(1-$C$1)*AC3 -> 2969.1037 | AF3: 5677 | AG3: =$C$1*AD3+(1-$C$1)*AE3 -> 3282.5726 | AH3: 3489 | AI3: =$C$1*AF3+(1-$C$1)*AG3 -> 4000.9008 | AJ3: 9050 | AK3: =$C$1*AH3+(1-$C$1)*AI3 -> 3847.3306 | AL3: 3450 | AM3: =$C$1*AJ3+(1-$C$1)*AK3 -> 5408.1314 | AN3: =ABS(AL3-AM3) -> 1958.1314 | AO3: =IFERROR(ABS((AL3-AM3)/AL3),"0") -> 0.56757432
A4: FAC0465 | B4: CABLE TIE REMOVE SIZ11-12" W4.5-4.8mm BK | C4: =_xlfn.XLOOKUP(A4,Fore!A:A,Fore!AC:AC) -> AY | D4: 0 | E4: =D4 -> 0 | F4: 0 | G4: =$C$1*D4+(1-$C$1)*E4 -> 0 | H4: 0 | I4: =$C$1*F4+(1-$C$1)*G4 -> 0 | J4: 4300 | K4: =$C$1*H4+(1-$C$1)*I4 -> 0 | L4: 1005 | M4: =$C$1*J4+(1-$C$1)*K4 -> 1290 | N4: 3200 | O4: =$C$1*M4+(1-$C$1)*L4 -> 1090.5 | P4: 7800 | Q4: =$C$1*N4+(1-$C$1)*O4 -> 1723.35 | R4: 7894 | S4: =$C$1*P4+(1-$C$1)*Q4 -> 3546.345 | T4: 8183 | U4: =$C$1*R4+(1-$C$1)*S4 -> 4850.6415 | V4: 4000 | W4: =$C$1*T4+(1-$C$1)*U4 -> 5850.349 | X4: 3738 | Y4: =$C$1*V4+(1-$C$1)*W4 -> 5295.2443 | Z4: 200 | AA4: =$C$1*X4+(1-$C$1)*Y4 -> 4828.071 | AB4: 1900 | AC4: =$C$1*Z4+(1-$C$1)*AA4 -> 3439.6497 | AD4: 3885.75 | AE4: =$C$1*AB4+(1-$C$1)*AC4 -> 2977.7548 | AF4: 3966 | AG4: =$C$1*AD4+(1-$C$1)*AE4 -> 3250.1534 | AH4: 3204.999 | AI4: =$C$1*AF4+(1-$C$1)*AG4 -> 3464.9074 | AJ4: 5798.333 | AK4: =$C$1*AH4+(1-$C$1)*AI4 -> 3386.9348 | AL4: 1100.667 | AM4: =$C$1*AJ4+(1-$C$1)*AK4 -> 4110.3543 | AN4: =ABS(AL4-AM4) -> 3009.6873 | AO4: =IFERROR(ABS((AL4-AM4)/AL4),"0") -> 2.7344213
A5: FST-0298 | B5: M8 FLAT WASHER SS | C5: =_xlfn.XLOOKUP(A5,Fore!A:A,Fore!AC:AC) -> AY | D5: 0 | E5: =D5 -> 0 | F5: 0 | G5: =$C$1*D5+(1-$C$1)*E5 -> 0 | H5: 0 | I5: =$C$1*F5+(1-$C$1)*G5 -> 0 | J5: 1580 | K5: =$C$1*H5+(1-$C$1)*I5 -> 0 | L5: 700 | M5: =$C$1*J5+(1-$C$1)*K5 -> 474 | N5: 2473.3336 | O5: =$C$1*M5+(1-$C$1)*L5 -> 632.2 | P5: 3777.5 | Q5: =$C$1*N5+(1-$C$1)*O5 -> 1184.5401 | R5: 4183.5 | S5: =$C$1*P5+(1-$C$1)*Q5 -> 1962.4281 | T5: 2838.5 | U5: =$C$1*R5+(1-$C$1)*S5 -> 2628.7496 | V5: 1850 | W5: =$C$1*T5+(1-$C$1)*U5 -> 2691.6747 | X5: 2758 | Y5: =$C$1*V5+(1-$C$1)*W5 -> 2439.1723 | Z5: 392 | AA5: =$C$1*X5+(1-$C$1)*Y5 -> 2534.8206 | AB5: 1000 | AC5: =$C$1*Z5+(1-$C$1)*AA5 -> 1891.9744 | AD5: 3933 | AE5: =$C$1*AB5+(1-$C$1)*AC5 -> 1624.3821 | AF5: 5067 | AG5: =$C$1*AD5+(1-$C$1)*AE5 -> 2316.9675 | AH5: 4510 | AI5: =$C$1*AF5+(1-$C$1)*AG5 -> 3141.9772 | AJ5: 9100 | AK5: =$C$1*AH5+(1-$C$1)*AI5 -> 3552.3841 | AL5: 1678 | AM5: =$C$1*AJ5+(1-$C$1)*AK5 -> 5216.6688 | AN5: =ABS(AL5-AM5) -> 3538.6688 | AO5: =IFERROR(ABS((AL5-AM5)/AL5),"0") -> 2.1088611
A6: 9965-0009-T | B6: FLAT WASHER M16 CLASS10 ZINC PLATED | C6: =_xlfn.XLOOKUP(A6,Fore!A:A,Fore!AC:AC) -> AY | D6: 2862 | E6: =D6 -> 2862 | F6: 3150 | G6: =$C$1*D6+(1-$C$1)*E6 -> 2862 | H6: 3200.0008 | I6: =$C$1*F6+(1-$C$1)*G6 -> 2948.4 | J6: 656 | K6: =$C$1*H6+(1-$C$1)*I6 -> 3023.8802 | L6: 1183 | M6: =$C$1*J6+(1-$C$1)*K6 -> 2313.5162 | N6: 2149.0001 | O6: =$C$1*M6+(1-$C$1)*L6 -> 1522.1549 | P6: 3138.9999 | Q6: =$C$1*N6+(1-$C$1)*O6 -> 1710.2084 | R6: 6278 | S6: =$C$1*P6+(1-$C$1)*Q6 -> 2138.8459 | T6: 3600 | U6: =$C$1*R6+(1-$C$1)*S6 -> 3380.5921 | V6: 4162 | W6: =$C$1*T6+(1-$C$1)*U6 -> 3446.4145 | X6: 3100 | Y6: =$C$1*V6+(1-$C$1)*W6 -> 3661.0901 | Z6: 100 | AA6: =$C$1*X6+(1-$C$1)*Y6 -> 3492.7631 | AB6: 1500 | AC6: =$C$1*Z6+(1-$C$1)*AA6 -> 2474.9342 | AD6: 800 | AE6: =$C$1*AB6+(1-$C$1)*AC6 -> 2182.4539 | AF6: 2015 | AG6: =$C$1*AD6+(1-$C$1)*AE6 -> 1767.7177 | AH6: 3132 | AI6: =$C$1*AF6+(1-$C$1)*AG6 -> 1841.9024 | AJ6: 2732 | AK6: =$C$1*AH6+(1-$C$1)*AI6 -> 2228.9317 | AL6: 1945 | AM6: =$C$1*AJ6+(1-$C$1)*AK6 -> 2379.8522 | AN6: =ABS(AL6-AM6) -> 434.85219 | AO6: =IFERROR(ABS((AL6-AM6)/AL6),"0") -> 0.22357439
A7: FST-0291 | B7: M6 WASHER SS | C7: =_xlfn.XLOOKUP(A7,Fore!A:A,Fore!AC:AC) -> AY | D7: 0 | E7: =D7 -> 0 | F7: 0 | G7: =$C$1*D7+(1-$C$1)*E7 -> 0 | H7: 0 | I7: =$C$1*F7+(1-$C$1)*G7 -> 0 | J7: 1400 | K7: =$C$1*H7+(1-$C$1)*I7 -> 0 | L7: 3046 | M7: =$C$1*J7+(1-$C$1)*K7 -> 420 | N7: 1080 | O7: =$C$1*M7+(1-$C$1)*L7 -> 2258.2 | P7: 6007 | Q7: =$C$1*N7+(1-$C$1)*O7 -> 1904.74 | R7: 6513 | S7: =$C$1*P7+(1-$C$1)*Q7 -> 3135.418 | T7: 6345.4445 | U7: =$C$1*R7+(1-$C$1)*S7 -> 4148.6926 | V7: 3657 | W7: =$C$1*T7+(1-$C$1)*U7 -> 4807.7182 | X7: 2000 | Y7: =$C$1*V7+(1-$C$1)*W7 -> 4462.5027 | Z7: 0 | AA7: =$C$1*X7+(1-$C$1)*Y7 -> 3723.7519 | AB7: 2200 | AC7: =$C$1*Z7+(1-$C$1)*AA7 -> 2606.6263 | AD7: 2416 | AE7: =$C$1*AB7+(1-$C$1)*AC7 -> 2484.6384 | AF7: 3200 | AG7: =$C$1*AD7+(1-$C$1)*AE7 -> 2464.0469 | AH7: 3000 | AI7: =$C$1*AF7+(1-$C$1)*AG7 -> 2684.8328 | AJ7: 2192 | AK7: =$C$1*AH7+(1-$C$1)*AI7 -> 2779.383 | AL7: 200 | AM7: =$C$1*AJ7+(1-$C$1)*AK7 -> 2603.1681 | AN7: =ABS(AL7-AM7) -> 2403.1681 | AO7: =IFERROR(ABS((AL7-AM7)/AL7),"0") -> 12.01584
A8: FST-0304 | B8: M10-1.5 HH LOCK NUT SS | C8: =_xlfn.XLOOKUP(A8,Fore!A:A,Fore!AC:AC) -> AY | D8: 0 | E8: =D8 -> 0 | F8: 0 | G8: =$C$1*D8+(1-$C$1)*E8 -> 0 | H8: 0 | I8: =$C$1*F8+(1-$C$1)*G8 -> 0 | J8: 950 | K8: =$C$1*H8+(1-$C$1)*I8 -> 0 | L8: 2950 | M8: =$C$1*J8+(1-$C$1)*K8 -> 285 | N8: 2126 | O8: =$C$1*M8+(1-$C$1)*L8 -> 2150.5 | P8: 4320.3333 | Q8: =$C$1*N8+(1-$C$1)*O8 -> 2143.15 | R8: 5769 | S8: =$C$1*P8+(1-$C$1)*Q8 -> 2796.305 | T8: 4400.5 | U8: =$C$1*R8+(1-$C$1)*S8 -> 3688.1135 | V8: 4337 | W8: =$C$1*T8+(1-$C$1)*U8 -> 3901.8294 | X8: 3200 | Y8: =$C$1*V8+(1-$C$1)*W8 -> 4032.3806 | Z8: 0 | AA8: =$C$1*X8+(1-$C$1)*Y8 -> 3782.6664 | AB8: 50 | AC8: =$C$1*Z8+(1-$C$1)*AA8 -> 2647.8665 | AD8: 2085.79 | AE8: =$C$1*AB8+(1-$C$1)*AC8 -> 1868.5065 | AF8: 1235 | AG8: =$C$1*AD8+(1-$C$1)*AE8 -> 1933.6916 | AH8: 2499 | AI8: =$C$1*AF8+(1-$C$1)*AG8 -> 1724.0841 | AJ8: 3169 | AK8: =$C$1*AH8+(1-$C$1)*AI8 -> 1956.5589 | AL8: 1550 | AM8: =$C$1*AJ8+(1-$C$1)*AK8 -> 2320.2912 | AN8: =ABS(AL8-AM8) -> 770.29121 | AO8: =IFERROR(ABS((AL8-AM8)/AL8),"0") -> 0.49696207
A9: FST-0290 | B9: M6 x1.00 LOCKNUT SS | C9: =_xlfn.XLOOKUP(A9,Fore!A:A,Fore!AC:AC) -> AY | D9: 0 | E9: =D9 -> 0 | F9: 0 | G9: =$C$1*D9+(1-$C$1)*E9 -> 0 | H9: 0 | I9: =$C$1*F9+(1-$C$1)*G9 -> 0 | J9: 800.6664 | K9: =$C$1*H9+(1-$C$1)*I9 -> 0 | L9: 1000 | M9: =$C$1*J9+(1-$C$1)*K9 -> 240.19992 | N9: 1000 | O9: =$C$1*M9+(1-$C$1)*L9 -> 772.05998 | P9: 2200.3336 | Q9: =$C$1*N9+(1-$C$1)*O9 -> 840.44198 | R9: 5488 | S9: =$C$1*P9+(1-$C$1)*Q9 -> 1248.4095 | T9: 4694.4445 | U9: =$C$1*R9+(1-$C$1)*S9 -> 2520.2866 | V9: 1530 | W9: =$C$1*T9+(1-$C$1)*U9 -> 3172.534 | X9: 339 | Y9: =$C$1*V9+(1-$C$1)*W9 -> 2679.7738 | Z9: 0 | AA9: =$C$1*X9+(1-$C$1)*Y9 -> 1977.5417 | AB9: 0 | AC9: =$C$1*Z9+(1-$C$1)*AA9 -> 1384.2792 | AD9: 1220 | AE9: =$C$1*AB9+(1-$C$1)*AC9 -> 968.99541 | AF9: 1500 | AG9: =$C$1*AD9+(1-$C$1)*AE9 -> 1044.2968 | AH9: 2280 | AI9: =$C$1*AF9+(1-$C$1)*AG9 -> 1181.0078 | AJ9: 428.571 | AK9: =$C$1*AH9+(1-$C$1)*AI9 -> 1510.7054 | AL9: 1099.429 | AM9: =$C$1*AJ9+(1-$C$1)*AK9 -> 1186.0651 | AN9: =ABS(AL9-AM9) -> 86.636098 | AO9: =IFERROR(ABS((AL9-AM9)/AL9),"0") -> 0.078800994
A10: FST-0297 | B10: M8-1.25 LOCKNUT SS | C10: =_xlfn.XLOOKUP(A10,Fore!A:A,Fore!AC:AC) -> AY | D10: 0 | E10: =D10 -> 0 | F10: 0 | G10: =$C$1*D10+(1-$C$1)*E10 -> 0 | H10: 0 | I10: =$C$1*F10+(1-$C$1)*G10 -> 0 | J10: 800 | K10: =$C$1*H10+(1-$C$1)*I10 -> 0 | L10: 66.6668 | M10: =$C$1*J10+(1-$C$1)*K10 -> 240 | N10: 1853.3334 | O10: =$C$1*M10+(1-$C$1)*L10 -> 118.66676 | P10: 2120.9998 | Q10: =$C$1*N10+(1-$C$1)*O10 -> 639.06675 | R10: 2600 | S10: =$C$1*P10+(1-$C$1)*Q10 -> 1083.6467 | T10: 1900 | U10: =$C$1*R10+(1-$C$1)*S10 -> 1538.5527 | V10: 1030 | W10: =$C$1*T10+(1-$C$1)*U10 -> 1646.9869 | X10: 917 | Y10: =$C$1*V10+(1-$C$1)*W10 -> 1461.8908 | Z10: 150 | AA10: =$C$1*X10+(1-$C$1)*Y10 -> 1298.4236 | AB10: 400 | AC10: =$C$1*Z10+(1-$C$1)*AA10 -> 953.8965 | AD10: 2500 | AE10: =$C$1*AB10+(1-$C$1)*AC10 -> 787.72755 | AF10: 1100 | AG10: =$C$1*AD10+(1-$C$1)*AE10 -> 1301.4093 | AH10: 2733 | AI10: =$C$1*AF10+(1-$C$1)*AG10 -> 1240.9865 | AJ10: 4136 | AK10: =$C$1*AH10+(1-$C$1)*AI10 -> 1688.5905 | AL10: 50 | AM10: =$C$1*AJ10+(1-$C$1)*AK10 -> 2422.8134 | AN10: =ABS(AL10-AM10) -> 2372.8134 | AO10: =IFERROR(ABS((AL10-AM10)/AL10),"0") -> 47.456268
A11: FST-0311 | B11: M12 WASHER SS | C11: =_xlfn.XLOOKUP(A11,Fore!A:A,Fore!AC:AC) -> AX | D11: 0 | E11: =D11 -> 0 | F11: 0 | G11: =$C$1*D11+(1-$C$1)*E11 -> 0 | H11: 0 | I11: =$C$1*F11+(1-$C$1)*G11 -> 0 | J11: 1100 | K11: =$C$1*H11+(1-$C$1)*I11 -> 0 | L11: 1500.0002 | M11: =$C$1*J11+(1-$C$1)*K11 -> 330 | N11: 1689.9998 | O11: =$C$1*M11+(1-$C$1)*L11 -> 1149.0001 | P11: 1260 | Q11: =$C$1*N11+(1-$C$1)*O11 -> 1311.3 | R11: 2421 | S11: =$C$1*P11+(1-$C$1)*Q11 -> 1295.91 | T11: 1532 | U11: =$C$1*R11+(1-$C$1)*S11 -> 1633.437 | V11: 3266 | W11: =$C$1*T11+(1-$C$1)*U11 -> 1603.0059 | X11: 318 | Y11: =$C$1*V11+(1-$C$1)*W11 -> 2101.9041 | Z11: 0 | AA11: =$C$1*X11+(1-$C$1)*Y11 -> 1566.7329 | AB11: 1116 | AC11: =$C$1*Z11+(1-$C$1)*AA11 -> 1096.713 | AD11: 1957.15 | AE11: =$C$1*AB11+(1-$C$1)*AC11 -> 1102.4991 | AF11: 772 | AG11: =$C$1*AD11+(1-$C$1)*AE11 -> 1358.8944 | AH11: 2228 | AI11: =$C$1*AF11+(1-$C$1)*AG11 -> 1182.8261 | AJ11: 2150 | AK11: =$C$1*AH11+(1-$C$1)*AI11 -> 1496.3782 | AL11: 0 | AM11: =$C$1*AJ11+(1-$C$1)*AK11 -> 1692.4648 | AN11: =ABS(AL11-AM11) -> 1692.4648 | AO11: =IFERROR(ABS((AL11-AM11)/AL11),"0") -> 0
A12: 9562-0014-T | B12: M16x2.0 DIN 980 Class 10 Zinc Lock Nut | C12: =_xlfn.XLOOKUP(A12,Fore!A:A,Fore!AC:AC) -> AY | D12: 3400 | E12: =D12 -> 3400 | F12: 300 | G12: =$C$1*D12+(1-$C$1)*E12 -> 3400 | H12: 1868 | I12: =$C$1*F12+(1-$C$1)*G12 -> 2470 | J12: 24 | K12: =$C$1*H12+(1-$C$1)*I12 -> 2289.4 | L12: 305 | M12: =$C$1*J12+(1-$C$1)*K12 -> 1609.78 | N12: 880 | O12: =$C$1*M12+(1-$C$1)*L12 -> 696.434 | P12: 1690.0001 | Q12: =$C$1*N12+(1-$C$1)*O12 -> 751.5038 | R12: 927.9999 | S12: =$C$1*P12+(1-$C$1)*Q12 -> 1033.0527 | T12: 1500 | U12: =$C$1*R12+(1-$C$1)*S12 -> 1001.5369 | V12: 1700 | W12: =$C$1*T12+(1-$C$1)*U12 -> 1151.0758 | X12: 200 | Y12: =$C$1*V12+(1-$C$1)*W12 -> 1315.7531 | Z12: 100 | AA12: =$C$1*X12+(1-$C$1)*Y12 -> 981.02714 | AB12: 500 | AC12: =$C$1*Z12+(1-$C$1)*AA12 -> 716.719 | AD12: 43 | AE12: =$C$1*AB12+(1-$C$1)*AC12 -> 651.7033 | AF12: 260 | AG12: =$C$1*AD12+(1-$C$1)*AE12 -> 469.09231 | AH12: 1367 | AI12: =$C$1*AF12+(1-$C$1)*AG12 -> 406.36462 | AJ12: 1750 | AK12: =$C$1*AH12+(1-$C$1)*AI12 -> 694.55523 | AL12: 450 | AM12: =$C$1*AJ12+(1-$C$1)*AK12 -> 1011.1887 | AN12: =ABS(AL12-AM12) -> 561.18866 | AO12: =IFERROR(ABS((AL12-AM12)/AL12),"0") -> 1.2470859
A13: FST-0301 | B13: M10-1.5 HH Bolt x 40 Lg. SS | C13: =_xlfn.XLOOKUP(A13,Fore!A:A,Fore!AC:AC) -> AY | D13: 0 | E13: =D13 -> 0 | F13: 0 | G13: =$C$1*D13+(1-$C$1)*E13 -> 0 | H13: 0 | I13: =$C$1*F13+(1-$C$1)*G13 -> 0 | J13: 529.9994 | K13: =$C$1*H13+(1-$C$1)*I13 -> 0 | L13: 800 | M13: =$C$1*J13+(1-$C$1)*K13 -> 158.99982 | N13: 860 | O13: =$C$1*M13+(1-$C$1)*L13 -> 607.69995 | P13: 1550 | Q13: =$C$1*N13+(1-$C$1)*O13 -> 683.38996 | R13: 1059 | S13: =$C$1*P13+(1-$C$1)*Q13 -> 943.37297 | T13: 894 | U13: =$C$1*R13+(1-$C$1)*S13 -> 978.06108 | V13: 661 | W13: =$C$1*T13+(1-$C$1)*U13 -> 952.84276 | X13: 655 | Y13: =$C$1*V13+(1-$C$1)*W13 -> 865.28993 | Z13: 80 | AA13: =$C$1*X13+(1-$C$1)*Y13 -> 802.20295 | AB13: 340 | AC13: =$C$1*Z13+(1-$C$1)*AA13 -> 585.54207 | AD13: 1420 | AE13: =$C$1*AB13+(1-$C$1)*AC13 -> 511.87945 | AF13: 650 | AG13: =$C$1*AD13+(1-$C$1)*AE13 -> 784.31561 | AH13: 2090 | AI13: =$C$1*AF13+(1-$C$1)*AG13 -> 744.02093 | AJ13: 1600 | AK13: =$C$1*AH13+(1-$C$1)*AI13 -> 1147.8146 | AL13: 240 | AM13: =$C$1*AJ13+(1-$C$1)*AK13 -> 1283.4703 | AN13: =ABS(AL13-AM13) -> 1043.4703 | AO13: =IFERROR(ABS((AL13-AM13)/AL13),"0") -> 4.3477927
A14: FST-0310 | B14: M12-1.75 LOCKNUT SS | C14: =_xlfn.XLOOKUP(A14,Fore!A:A,Fore!AC:AC) -> AY | D14: 0 | E14: =D14 -> 0 | F14: 0 | G14: =$C$1*D14+(1-$C$1)*E14 -> 0 | H14: 0 | I14: =$C$1*F14+(1-$C$1)*G14 -> 0 | J14: 700 | K14: =$C$1*H14+(1-$C$1)*I14 -> 0 | L14: 200 | M14: =$C$1*J14+(1-$C$1)*K14 -> 210 | N14: 874 | O14: =$C$1*M14+(1-$C$1)*L14 -> 203 | P14: 640 | Q14: =$C$1*N14+(1-$C$1)*O14 -> 404.3 | R14: 1239.5461 | S14: =$C$1*P14+(1-$C$1)*Q14 -> 475.01 | T14: 1200.4539 | U14: =$C$1*R14+(1-$C$1)*S14 -> 704.37083 | V14: 1706 | W14: =$C$1*T14+(1-$C$1)*U14 -> 853.19575 | X14: 596 | Y14: =$C$1*V14+(1-$C$1)*W14 -> 1109.037 | Z14: 0 | AA14: =$C$1*X14+(1-$C$1)*Y14 -> 955.12592 | AB14: 300 | AC14: =$C$1*Z14+(1-$C$1)*AA14 -> 668.58814 | AD14: 1607.72 | AE14: =$C$1*AB14+(1-$C$1)*AC14 -> 558.0117 | AF14: 650 | AG14: =$C$1*AD14+(1-$C$1)*AE14 -> 872.92419 | AH14: 1240 | AI14: =$C$1*AF14+(1-$C$1)*AG14 -> 806.04693 | AJ14: 1175 | AK14: =$C$1*AH14+(1-$C$1)*AI14 -> 936.23285 | AL14: 39 | AM14: =$C$1*AJ14+(1-$C$1)*AK14 -> 1007.863 | AN14: =ABS(AL14-AM14) -> 968.863 | AO14: =IFERROR(ABS((AL14-AM14)/AL14),"0") -> 24.842641
A15: FST-0356 | B15: M4 WASHER SS304 | C15: =_xlfn.XLOOKUP(A15,Fore!A:A,Fore!AC:AC) -> AY | D15: 0 | E15: =D15 -> 0 | F15: 0 | G15: =$C$1*D15+(1-$C$1)*E15 -> 0 | H15: 0 | I15: =$C$1*F15+(1-$C$1)*G15 -> 0 | J15: 0 | K15: =$C$1*H15+(1-$C$1)*I15 -> 0 | L15: 0 | M15: =$C$1*J15+(1-$C$1)*K15 -> 0 | N15: 900.0003 | O15: =$C$1*M15+(1-$C$1)*L15 -> 0 | P15: 2233.3351 | Q15: =$C$1*N15+(1-$C$1)*O15 -> 270.00009 | R15: 0 | S15: =$C$1*P15+(1-$C$1)*Q15 -> 859.00059 | T15: 2366.6646 | U15: =$C$1*R15+(1-$C$1)*S15 -> 601.30042 | V15: 1000 | W15: =$C$1*T15+(1-$C$1)*U15 -> 1130.9097 | X15: 0 | Y15: =$C$1*V15+(1-$C$1)*W15 -> 1091.6368 | Z15: 0 | AA15: =$C$1*X15+(1-$C$1)*Y15 -> 764.14574 | AB15: 0 | AC15: =$C$1*Z15+(1-$C$1)*AA15 -> 534.90202 | AD15: 1000 | AE15: =$C$1*AB15+(1-$C$1)*AC15 -> 374.43141 | AF15: 1000 | AG15: =$C$1*AD15+(1-$C$1)*AE15 -> 562.10199 | AH15: 1000 | AI15: =$C$1*AF15+(1-$C$1)*AG15 -> 693.47139 | AJ15: 1142 | AK15: =$C$1*AH15+(1-$C$1)*AI15 -> 785.42997 | AL15: 0 | AM15: =$C$1*AJ15+(1-$C$1)*AK15 -> 892.40098 | AN15: =ABS(AL15-AM15) -> 892.40098 | AO15: =IFERROR(ABS((AL15-AM15)/AL15),"0") -> 0
